Workbook

Sheet KEG. PENGAJIAN HARIAN
B1: TANGGAL | C1: BULAN | D1: DURASI | E1: NAMA GURU | F1: NAMA MURID | G1: KEHADIRAN | H1: MATERI: | I1: NO. WHATSAPP | J1: Field_bc728b1
A2: January 2, 2025 12:51 pm | B2: 45659 | C2: =TEXT(B2, "mmmm") -> Januari | D2: 0.039583333 | E2: Artha-JG | F2: Dwiki-RLG | G2: HADIR | H2: Opening #menjelaskan ttg ijektihad keimaman menikah dg sesama Jamaah #menjelaskan ttg tata cara sholat jum'at Bacaan: Surat Al baqoroh 38-42 👉 Alhamdulillah bacaannya cukup bagus kurang di "kaf sukun", dia baca seperti "kof sukun" Check hafalan -Doa berlindung dari syirik - Doa berlindung dari amal jelek - Doa kesabaran - Doa ketetapan iman - Doa minta ilham yg benar -Doa masuk pasar -Doa ketika ada petir -Doa melihat musibah -Doa ketika tertimpa musibah -mencari ilmu 1& 2 -Doa berbuka puasa -Doa ketika marah -Doa minum susu 👉Ada beberapa doa yg dia lupa, amsol di deres lagi doa2 nya Report Alhamdulillah Pengajian berjalan dg baik, tidak ada kendala. Semoga Alloh paring manfaat dan barokah. InsyaAllah ketemu lagi besok( katanya bisa ngaji tomorrow,after wake up) | I2: 6285606274880
A3: January 3, 2025 10:05 pm | B3: 45658 | C3: =TEXT(B3, "mmmm") -> Januari | D3: 0.038888889 | E3: Nedha-PWD | F3: Hafiz-PTM | G3: HADIR | H3: Bacaan Al-Baqarah (2) : 170-176 Alhamdulillah! Tetap terus dideres ketika dirumah nggeh. Murojaah hafalan (Al-haqoh : 40-52) Sudah lebih lancar daripada last meet, jangan lupa dideres terus ketika dirumah. Doa iftitah Alhamdulillah Hafiz sudah mengenal salah satu doa dalam sholat ini. Dan juga sudah lumayan hafal, good. Latihan pegon dasar Alhamdulillah sudah mulai bisa meletakkan huruf sesuai dengan posisinya yang benar, Today menulis pegon nama negara, alhamdulillah hanya sedikit yang keliru ketika menulisnya. Semoga Allah paring ilmu yang bermanfaat dan barokah, May Allah bless you 🌷💗 | I3: 6281232193915
A4: January 4, 2025 4:56 am | B4: 45661 | C4: =TEXT(B4, "mmmm") -> Januari | D4: 0.034722222 | E4: Azki-MDN | F4: Denissa-RLG | G4: By VN | H4: Makna dan keterangan k. Jannah wannar bahasa indo hal. 41-42 By VN Alhamdulillah sudah dikerjakan Nissa Moga2 Allah paring lancar barokah amin | I4: 628972529354
A5: January 4, 2025 1:14 pm | B5: 45660 | C5: =TEXT(B5, "mmmm") -> Januari | D5: 0.036111111 | E5: Artha-JG | F5: Dwiki-RLG | G5: HADIR | H5: Opening Bacaan Al Baqarah ayat 43-48 Alhamdulillah bacaannya cukup bagus, lancar Makna Adilah 83-84 Report Alhamdulillah pengajian berjalan lancar, semoga Alloh paring manfaat dan barokah | I5: 6285606274880
A6: January 5, 2025 2:51 am | B6: 45662 | C6: =TEXT(B6, "mmmm") -> Januari | D6: 0.029166667 | E6: Azki-MDN | F6: Denissa-RLG | G6: HADIR | H6: 1. Bacaan QS Al Baqarah 188-190 > Mbak azki membaca Nissa mengulang, tapi masih di temui kurang panjang pendeknya, *amal Solih banyak menders ya Nisa* 2. Makna hadits Jannah wannar bahasa Indonesia hal. 42-43 > Alhamdulillah Nissa mengikuti makna dengan baik dan teliti karena pas saya salah baca mau di benerin, *thank you Nissa* 3. Membaca keterangan hadits 4. Nasehat bahasa Indonesia tentang hijab Moga2 Allah paring manfaat dan barokah untuk semuanya | I6: 628972529354
A7: January 5, 2025 2:25 pm | B7: 45661 | C7: =TEXT(B7, "mmmm") -> Januari | D7: 0.03125 | E7: Wulan-PWD | F7: Chester-PD | G7: HADIR | H7: 1. Baca tilawati - tilawati 5 page 6 ( 3 line from the bottom ) > Alhamdulillah Chester mau baca berulang ulang, sehingga bacaanya sudah lumayan bagus, juga review 2 baris sebelumnya juga 2. Murajaah surat > Chester mau baca semua surat yang sudah dia hafal lewat screen, ternyata ada beberapa ayat dan surat yang chester lupa, nanti bisa dimurajaah kembali atau Chester bisa baca baca Suratnya buat balikin hafalannya chester . 3. Surat Al Kausar > Good boy, hanya 3 ayat insyaalloh easy buat Chester, jangan sampai lupa ya, nanti dideres setiap ngaji juga bisa. 4. Write kitabaty > Chester nulisnya buru buru atau bagaimana,sehingga tulisannya agak sedikit kurang rapi, Report: I am sorry chester, ngajinya nggak bisa lama, soalnya mba Wulan ngajar 3 murid dengan waktu yang berurutan, waktu dengan chester jadi berkurang, 🙏 Semoga alloh paring menjadi anak yang berbakti kepada kedua orang tua, sukses Dunia akhirot nya, cerdas, alim Dan faqih, mandiri, faham, dan kebarokahan ilmu yang bermanfaat, aamiin ya robbal alamin 🤲🤲🤲 | I7: 6282231661306
A8: January 5, 2025 3:06 pm | B8: 45659 | C8: =TEXT(B8, "mmmm") -> Januari | D8: 0.040277778 | E8: Millati-PWD | F8: Abell-NH | G8: HADIR | H8: Tilawati 3 halaman 19 > Abell ada beberapa yang kurang lancar di akhir dia baca. Alhamdulillah kebanyakan sudah lancar, tinggal menderes lagi yaa. Doa- Doa - Pagi dan sore - Raja Istighfar - Ketetapan Iman - Mencari ilmu yang bermanfaat - Minta ilham yang baik - Berpakaian - Minta kesabaran - Ketika bersin - Untuk kedua orang tua - Masuk dan keluar rumah - Berdiri dari Duduk > Alhamdulillah, Abell sudah hafal banyak doa diatas. Abell bisa cepet hafalnya. Kerenn. Masih ada beberapa doa spt minta kesabaran, masuk rumah, doa berpakaian, Abell masih repeat. But that's fine. Di akhir pengajian membaca doa berdiri dari duduk sebagai pembiasaan. Goodjob girl Murajaah Surat - Al Lahab - An Nashr - Al Kafirun - Al Maun - Al Humazah - At Takatsur - Al Ashr > Insyaallah Abell sudah hafal banyak surat, mungkin lebih banyak di murajaah lagi ya, Abell. Biar makin lancar hafalannya. Bacaan Sholat > Insyaallah semua doa solat Abell sudah lancar. Cuman Abell bilang masih bingung antara doa iftitah dan doa tasyahud. Tapi, setelah dijelaskan, Alhamdulillah Abell paham dengan baik. Asmaul Husna 1-30 > Abell sudah 100% hafal mulai 1-20. Congrats girl👏👏tinggal 21-30. Jadi Abell masih repeat | I8: 6285707668655
A9: January 5, 2025 11:26 pm | B9: 45660 | C9: =TEXT(B9, "mmmm") -> Januari | D9: 0.025694444 | E9: Rika-KDR | F9: Liv-CH | G9: HADIR | H9: *BERDO'A BEFORE NGAJI, CLAP2, NYANYI2* *BACAAN* Tilawati 1 page 12 *HAFALAN* Asmaul husna 1-20 | I9: 6285746146893
A10: January 5, 2025 11:40 pm | B10: 45663 | C10: =TEXT(B10, "mmmm") -> Januari | D10: 0 | E10: Rika-KDR | F10: Liv-CH | G10: IZIN (MURID) | H10: She is not in good mood, so we cancel the ngaji | I10: 6285746146893
A11: January 6, 2025 12:09 am | B11: 45662 | C11: =TEXT(B11, "mmmm") -> Januari | D11: 0.020833333 | E11: Fauzan-SL3 | F11: Gabriel-CH | G11: HADIR | H11: 1. Baca tilawati 4 halaman 44 > Alhamdulillah Gabriel bisa membaca dengan cukup baik tapi masih perlu diulang 2. PR - Membaca Tilawati 4 hal 44 - Menulis Doa keluar masjid Semoga Alloh paring kemudahan, kelancaran, kebarokahan dan ilmu yang bermanfaat, aamiin 🤲 | I11: 6285291035544
A12: January 6, 2025 3:54 am | B12: 45663 | C12: =TEXT(B12, "mmmm") -> Januari | D12: 0.048611111 | E12: Azki-MDN | F12: Chester-PD | G12: HADIR | H12: 1. Membaca di screen Asmaul Husna 1-60 > Alhamdulillah very good kalo pas hafal dia tidak baca ke layar 2. Membaca semua bacaan-bacaan sholat > Alhamdulillah very good kalau bacaannya sudah hafal dia tidak liat screen, tapi katanya hari ini tidak solat 😢 3. Membaca tilawati 5 hal. 7 baris ke 1-4 > Alhamdulillah chester mau membaca diulang-ulang hingga benar, sehingga boleh lanjut ke baris 5 di pertemuan berikutnya 4. Menulis 4 Roda berputar bahasa Indonesia dan penjelasan 4 Roda berputar > Alhamdulillah saat di minta jelaskan ulang poin 1 Alhamdulillah 90% Chester bisa menjelaskan nya *Pesan* *mohon amal solih chester di jaga Solat 5 Waktunya* Moga2 Allah paring manfaat barokah untuk semuanya amin | I12: 628972529354
A13: January 6, 2025 4:08 am | B13: 45661 | C13: =TEXT(B13, "mmmm") -> Januari | D13: 0 | E13: Mora-MLG | F13: Khadijah-RLG | G13: IZIN (MURID) | H13: Masih perjalanan | I13: 6285173431354
... A298: February 11, 2025 10:19 pm | B298: 45699 | C298: =TEXT(B298, "mmmm") -> Februari | D298: 0.020833333 | E298: Fadly-SMG | F298: Mikail-CH | G298: HADIR | H298: Bacaan - Tilawati 5 hal 27 > Alhamdulillah bacaannya bagus dan bisa fokus Materi lain - menjelaskan tenatang kefadholan puasa > Mikail sudah banyak mengerti dan paham tentan kefadholan puasa Semoga Allah paring manfaat lancar dan barokah | I298: 6281332534354
A299: February 12, 2025 1:19 am | B299: 45699 | C299: =TEXT(B299, "mmmm") -> Februari | D299: 0.036111111 | E299: Rika-KDR | F299: Rambo-CH | G299: HADIR | H299: *Brdo'a before ngaji* *BACAAN* > Q.S Al-Imron ayt. 170-173 *HAFALAN* Do'a Mohon Kesehatan 60% 2. An-Nas 3. Al-Falaq 4. Al-Ikhlas 5. Al-Lahab 6. An-Nashr 7. Al-Kafirun 8. Al-Kautsar 9. Al-Ma’un Asmaul hussna 1-50 Q.S Al-'Adiyat ( ayat 4 sering ke skip, dan ayt 8 akhir2nnya sering kliru ) *KEILMUAN* Menulis Arab Rangkaian Kata ( Q.S Al-Imron ayt. 170 ) > Membaca opening speech Semoga Allah paring barokah untuk mas rambo... Amiinn.. | I299: 6285746146893 | L299: \
A300: February 12, 2025 3:21 am | B300: 45700 | C300: =TEXT(B300, "mmmm") -> Februari | D300: 0.025694444 | E300: Rika-KDR | F300: Rambo-CH | G300: HADIR | H300: *Berdo'a before ngaji* > mencari ilmu yg bermanfaat 1 > mencari ilmu yg bermanfaat 2 > minta ilham yg baik > nabi musa *BACAAN* Q.S Al-Imron ayt. 178-180 > tinggal memperlancar madtobi'i nya, karena kadang yg seharusnya di baca pendek, mas rabo bacanya kepanjangan *HAFALAN* Do'a Mohon Kesehatan 85% 2.Ketika Akan Tidur dan Bangun Tidur 3.Ketika Akan Makan dan Selesai Makan 4.Kebaikan Dunia dan Akhirat 5.Untuk Kedua Orang Tua 6.Masuk dan Keluar WC 7.Sebelum dan Sesudah Wudhu 8.Minum Susu Asmaul Husna 1-45 *KEILMUAN* > Mention 29 karakter ( kecuali 6 thobi’at luhur, 4 maqodirulloh no.3-4 ) Semoga Allah paring manfaat dan barokah.. Amiinn... | I300: 6285746146893
A301: February 12, 2025 3:26 am | B301: 45700 | C301: =TEXT(B301, "mmmm") -> Februari | D301: 0.019444444 | E301: Rika-KDR | F301: Khayri-CH | G301: HADIR | H301: *Berdo'a before ngaji* *BACAAN* Tilawati 2 Hal 15 > Alkhamdulillah lumayan lancar, cuma kadang antara "AN, IN, UN" terbalik2 *HAFALAN* Q.S Al-Lahab Masuk dak Keluar Rumah Pagi dan Sore Asmaul husna 1-25 Semogga Allah paring manfaat dan barokah.. Amiinn... | I301: 6285746146893
A302: February 12, 2025 3:53 am | B302: 45698 | C302: =TEXT(B302, "mmmm") -> Februari | D302: 0.039583333 | E302: Rika-KDR | F302: Fitri-CND | G302: HADIR | H302: *BACAAN* > Q.S Al-Baqarah ayt. 30-33 ( mohon lebih di perhaikan panjang pendeknya ya fitrii ) *MAKNA* > Q.S Mursalat ayt. 1-19 *HAFALAN* Do'a Mohon Kesehatan .Ketetapan Iman Minta Ilmu yang Bermanfaat 1 Minta Ilmu yang Bermanfaat 2 Minta Ilham yang Baik Nabi Musa Masuk dan Keluar Rumah .Pagi dan Sore Masuk dan Keluar Masjid Memakai Pakaian *KEILMUAN* > Brush up materi 3 prinsip kerja jama'ah *PR* > Menderes Do'a Mohon Kesehatan > Menderes Q.S Al-Baqarah ayt. 34-37 Semoga Fitri menjadi anak yg sholikhat dan menjadi ladang pahala untuk ayah dan bunda.. Amiin.. | I302: 6285746146893
A303: February 12, 2025 4:09 am | B303: 45699 | C303: =TEXT(B303, "mmmm") -> Februari | D303: 0.032638889 | E303: Rika-KDR | F303: Nadeen-CH | G303: HADIR | H303: *OPENING, ICE BREAKING, TEPUK2, NYAYI2, BERDO'A* *BACAAN* QS. Al Baqarah 116-119 *HAFALAN* Review Asmaul Husna 1-99 > di catatan asmau husna nya mb nadeen tidak ada nomornya, jadi terkadang kalau ingin membenarkan yg salah umayan bingung, harus cari2 dulu, tapi alkhamdulillah tadi ketemu "yaa Wali" yg sempat missing Doa dan dzikir setelah sholat Doa ketetapan iman Doa minta ilmu yang manfaat Doa minta ilham yang baik Doa masuk rumah Doa keluar rumah Doa pagi dan sore Doa masuk dan keluar masjid Doa memakai pakaian Doa ketika berbuka puasa Review *doa berlindung dari sifat munafik* > ( minggu lalu sempat hafal 70% tanpa reading, tp hari ini sudah lupa lagi, nanti di review lagi yaa mbak nadeenn ) *KEILMUAN* > Latihan Pegon Dasar ( 3 soal, lumayan panjang hari ini pegonnya, per number 2 kalimat, jadi untuk connected nya mbak nadeen masih perlu belajar lagi ) *PR* - Menderes QS. Al Baqarah 120-123 - Murojaah Do'a berlindung dari sifat munafik Insya Allah nanti mb rika kirim gambar pegon sambung (pegon connected), dan mohon amal sholih bunda atau yg lain bisa di print kan, jadi nanti mb nadeen saat pelajaran menulis pegon bisa sambil melihat catatannya.. Semoga Allah paring barokah.. Amiinn.. | I303: 6285746146893
A304: February 12, 2025 11:37 am | B304: 45697 | C304: =TEXT(B304, "mmmm") -> Februari | D304: 0.038888889 | E304: Nedha-PWD | F304: Hafiz-PTM | G304: HADIR | H304: Bacaan QS al-baqarah (2) : 247-248 Alhamdulillah good, tetap disemangatkan didalam menderesnya. Murojaah (Al-Qolam) Alhamdulillah good, diperhatikan juga panjang pendeknya. Dan jangan buru-buru bacanya yaa. Setoran hafalan (Al-maarij') Alhamdulillah sudah hafal sampai selesai, good! Dideres lagi dan diperhatikan hukum tajwid yang juga nggeh. Asmaul husna 1-30 Alhamdulillah lumayan, tapi beberapa kali suka muter ke yaa musawwiru. Dideres lagi nggeh. Materi; Menghina, mencela, & meremehkan Alhamdulillah good! Bisa memahami dan memperhatikan apa yang sudah mba Nedha sampaikan dan juga ketika diberi kesempatan untuk memberikan contoh, Hafiz bisa mencontohkan. Semoga Allah paring ilmu yang manfaat dan barokah 💐✨ | I304: 6281232193915
A305: February 12, 2025 11:42 am | B305: 45697 | C305: =TEXT(B305, "mmmm") -> Februari | D305: 0.04375 | E305: Nedha-PWD | F305: Fitri-CND | G305: HADIR | H305: Bacaan QS al-baqarah (2) : 27-29 Fitri ditertibkan lagi yaa menderesnya dirumah, diusahakan sehari Menderes minimal 3 ayat/ lebih banyak lebih baik. Juga dipelajari lagi tajwid yang sudah pernah disampaikan, dan supaya diterapkan didalam bacaannya Makna QS an-Naba :31-40 Alhamdulillah good! Bisa memahami dan menangkap maksud isi ayat yang sudah disampaikan. Hafalan (at-takatsur) Alhamdulillah good, sudah lancar. Doa minta kesehatan Supaya dideres lagi, but alhamdulillah sudah lumayan lancar. Tajwid Qolqolah Alhamdulillah mengerti dengan apa yang sudah disampaikan, harapannya supaya bisa juga menerapkan didalam bacaannya. Hafalan "1.Asmaul Husna ( 1 – 99 ) 2.Ketika Akan Tidur dan Bangun Tidur 3.Ketika Akan Makan dan Selesai Makan 4.Kebaikan Dunia dan Akhirat 5.Untuk Kedua Orang Tua 6.Masuk dan Keluar WC 7.Sebelum dan Sesudah Wudhu 8.Minum Susu 9.Dzikir sesudah Sholat" Alhamdulillah sudah lumayan baik untuk hafalannya, supaya juga dipraktikkan ketika dirumah yaa. Semoga Allah paring ilmu yang manfaat dan barokah, serta bisa menjadi generus yang meneruskan perjuangan QHJ 💐✨💗 | I305: 6281232193915
A306: February 12, 2025 11:49 am | B306: 45699 | C306: =TEXT(B306, "mmmm") -> Februari | D306: 0.035416667 | E306: Nedha-PWD | F306: Hafiz-PTM | G306: HADIR | H306: Bacaan QS al-baqarah (2) : 249-252 Alhamdulillah good! Tetap memperhatikan panjang pendeknya yaa Asmaul husna 1-30 Disemangatkan lagi menghafalkannya!! Sudah lumayan hafal. Murojaah QS al-Haqqoh Alhamdulillah good, ada 1/2 ayat yang tertukar tadi but overall is good! Mengetahui Quran Hadist Jamaah (QHJ) Alhamdulillah ketika selesai menyampaikan materi, Hafiz diberi kesempatan untuk menjelaskan ulang sesuai dengan apa yang dia fahami. Dan alhamdulillah it's good, Hafiz bisa menyampaikan ulang secara singkat pengertian dari QHJ. Semoga Allah qodar menjadi generus yang bisa meneruskan perjuangan bapak Imam! May Allah bless you 💗✨ | I306: 6281232193915
A307: February 12, 2025 11:54 am | B307: 45700 | C307: =TEXT(B307, "mmmm") -> Februari | D307: 0.04375 | E307: Nedha-PWD | F307: Hafiz-PTM | G307: HADIR | H307: Bacaan QS al-baqarah (2) : 253-254 Alhamdulillah lancar dan good, tetap dirutinkan menderesnya dirumah New Hafalan (dibaca) QS Nuh : 1-3 PR dirumah untuk menghafalkannya nggeh. Asmaul husna 1-30 Tetap semangat menghafalkannya nggeh, masih suka kembali ke yaa musawwiru Menulis/mengenal pegon baku & pegon sambung Alhamdulillah Hafiz baru mencoba buat mengenal beberapa pegon baku. PR nya jangan lupa dikerjakan nggeh. Review materi Quran Hadist Jamaah Alhamdulillah bisa kembali menjelaskan materi yang sudah dijelaskan kemarin. Semoga Allah paring ilmu yang manfaat dan barokah! 🥰✨ | I307: 6281232193915
A308: February 12, 2025 2:50 pm | B308: 45700 | C308: =TEXT(B308, "mmmm") -> Februari | D308: 0.035416667 | E308: Artha-JG | F308: Dwiki-RLG | G308: HADIR | H308: Bacaan Al Baqarah 74-76 👉Alhamdulillah cukup lancar, tetap usahakan banyak nderes ya Dwiki Makna kitabuadilah 88-89 Menjelaskan ulang ttg mansuh,nanseh, cara junub, hal2 yang mengharuskan seseorang wajib junub, menjelaskan lagi ttg zina, jilid ranjam dan konsekuensi dari zina. 👉Saya jelaskan ulang karna Dwiki lupa Report Alhamdulillah pengajian berjalan lancar, di beberapa minggu ini banyak penjelasan tentang married stuff karena memang sesuai dg babnya di hadis adilah. Saya sudah jelaskan sak pol kemampuan saya, semoga Alloh paring Dwiki mengerti dan faham dg penjelasan saya dan semoga Alloh paring manfaat dan barokah. Aamiiin🤲 Tadi sudah saya kirimi catatan, mudah2 an Dwiki nggak lupa untuk copy on his notebook biar nggak lupa 😅mohon bantu ingatkan dwiki nggih pak zaenal/ mbak Erna | I308: 6285606274880
A309: February 13, 2025 1:19 am | B309: 45701 | C309: =TEXT(B309, "mmmm") -> Februari | D309: 0.020833333 | E309: Fauzan-SL3 | F309: Gabriel-CH | G309: HADIR | H309: 1. Baca tilawati 5 hal 6 > Alhamdulillah Gabriel bisa membaca dengan cukup baik tapi masih perlu diulangi 2. Menulis Doa keluar rumah 3. PR - Membaca Tilawati 5 hal 6 - Menghafal doa keluar rumah Semoga Alloh paring kemudahan, kelancaran, kebarokahan dan ilmu yang bermanfaat, | I309: 6285291035544
A310: February 13, 2025 4:44 am | B310: 45701 | C310: =TEXT(B310, "mmmm") -> Februari | D310: 0.063194444 | E310: Artha-JG | F310: Abi-BFL | G310: HADIR | H310: Opening Bacaan Surat al alaq 1-19 👉Alhamdulillah cukup lancar Makna jannah wannar 55-56 👉Alhamdulillah abi bisa memahami isi hdis dg baik Report 👉alhamdulillah tidak ada kendala karna Abi banyak membantu arrange the setences for explanation. Semoga Alloh paring manfaat dan barokah. Aamiiin | I310: 6285606274880
A311: February 13, 2025 3:51 pm | B311: 45700 | C311: =TEXT(B311, "mmmm") -> Februari | D311: 0.027777778 | E311: Mora-MLG | F311: Khadijah-RLG | G311: HADIR | H311: A. Bacaan Tilawati 2 Halaman 12 • It’s better than before. Dan tadi membaca 2x karena masih ada yg bingung sedikit2. Next amalsholeh mengulang dulu ya🥰 B. Murajaah Asmaul Husna 1-20 Surat al Fatihah Surat An Naas Surat Al Falaq Surat Al Ikhlas C. Mengetahui 4 tali keimanan • Point 1 dan 2. Mencoba untuk menjelskan dg bahasa yg murdah dimengerti | I311: 6285173431354
... A377: February 26, 2025 7:41 am | B377: 45699 | C377: =TEXT(B377, "mmmm") -> Februari | D377: 0.075694444 | E377: Ayu-CKP | F377: Kayla-CA | G377: HADIR | H377: • Bacaan surat Al Hijr 42-45 • Menghafal tajwid 5Bab dan mencari tajwid • Mangkulan Alquran Al Mulk 6-10 • Murojaah surat Albayyinah - Al ghariyah Mugo2Allah paring aman selamat lancar barokah, Allah paring ilmu yang bayak bermanfaat dan barokah Aamiin | I377: 62895632016027
A378: February 26, 2025 7:46 am | B378: 45706 | C378: =TEXT(B378, "mmmm") -> Februari | D378: 0.077083333 | E378: Ayu-CKP | F378: Kayla-CA | G378: HADIR | H378: ===================== *LAPORAN PENGAJIAN PPG* ===================== ● *Murid* : Kayla-CA ● *Tanggal* : 2025-02-11 ● *Guru* : Ayu-CKP ● *Durasi* : 01:49 ● *Kehadiran* : HADIR ● *Materi:* • Bacaan surat Al Hijr 42-45 • Menghafal tajwid 5Bab dan mencari tajwid • Mangkulan Alquran Al Mulk 6-10 • Murojaah surat Albayyinah - Al ghariyah Mugo2Allah paring aman selamat lancar barokah, Allah paring ilmu yang bayak bermanfaat dan barokah Aamiin الحمدلله جزاكم الله خيرا -> #ERROR! | I378: 62895632016027
A379: February 26, 2025 7:47 am | B379: 45695 | C379: =TEXT(B379, "mmmm") -> Februari | D379: 0.074305556 | E379: Ayu-CKP | F379: Abell-NH | G379: HADIR | H379: • Bacaan tilawaty 3 Hal 24 • Menghafal tajwid 5Bab dan mencari tajwid • Mangkulan Alquran Al Mulk 6-10 • Murojaah surat Albayyinah - Al ghariyah Mugo2Allah paring aman selamat lancar barokah, Allah paring ilmu yang bayak bermanfaat dan barokah Aamiin | I379: 62895632016027
A380: February 26, 2025 7:50 am | B380: 45702 | C380: =TEXT(B380, "mmmm") -> Februari | D380: 0.089583333 | E380: Ayu-CKP | F380: Abell-NH | G380: HADIR | H380: • Bacaan surat Al Hijr 42-45 • Menghafal tajwid 5Bab dan mencari tajwid • Mengahafal doa masuk rumah dan keluar rumah • Murojaah surat Albayyinah - Al ghariyah Mugo2Allah paring aman selamat lancar barokah, Allah paring ilmu yang bayak bermanfaat dan barokah Aamiin الحمدلله جزاكم الله خيرا | I380: 62895632016027
A381: February 26, 2025 7:52 am | B381: 45709 | C381: =TEXT(B381, "mmmm") -> Februari | D381: 0.079861111 | E381: Ayu-CKP | F381: Abell-NH | G381: HADIR | H381: • Bacaan surat Al Hijr 42-45 • Menghafal tajwid 5Bab dan mencari tajwid • Mengahafal doa masuk rumah dan keluar rumah • Murojaah surat Albayyinah - Al ghariyah Mugo2Allah paring aman selamat lancar barokah, Allah paring ilmu yang bayak bermanfaat dan barokah Aamiin | I381: 62895632016027
A382: February 26, 2025 1:07 pm | B382: 45709 | C382: =TEXT(B382, "mmmm") -> Februari | D382: 0.01875 | E382: Nedha-PWD | F382: Khadijah-RLG | G382: HADIR | H382: Bacaan Tilawati 2 hal. 13 Alhamdulillah sebenernya khadijah bisa, but beberapa memang kadang masih ragu-ragu. It's okey keep learning!! Review; -dzikir after sholat -an nas Alhamdulillah lancar good! NB: in hurry because of khadijah have another schedule, that's ngaji with mba dara. Semoga Allah paring ilmu yang manfaat dan barokah 💗 | I382: 6281232193915
A383: February 26, 2025 1:27 pm | B383: 45714 | C383: =TEXT(B383, "mmmm") -> Februari | D383: 0.04375 | E383: Nedha-PWD | F383: Khadijah-RLG | G383: HADIR | H383: Review surat pendek & Asmaul husna. Alhamdulillah khadijah bisa, tapi harus dipancing dulu seperti biasa. Baru mau nerusin 😂 Untuk asmaul husna supaya sering dibaca ketika dirumah yaa. Doa keluar rumah Kayaknya minggu lalu khadijah hafal lancar deh, why today bacanya minta repeat after mba nedha? 4 Tali keimanan (berdoa) Alhamdulillah khadijah bisa explain kalau berdoa itu minta nya ke Allah. Dan dia juga jelasin perbuatan buruk itu temennya Satan, dan kalau baik itu temannya the angel. Juga waktu ditanya khadijah doain siapa aja? Dia jawabnya untuk ibu, bapak, mas Shodiq dan juga mba zahra, that's good!! Tilawati 2 hal. 13 Today khadijah sedikit ngeluarin uneg-uneg nya, she said 'I think this tilawati it's pretty hard for me' 😂😭 And when I ask why? Khadijah nunjukin tilawati yang jilid 6 ahahaha, sudah overthinking duluan anaknya. But walaupun gamau baca dan merasa sedih kalau tilawati time by time become harder, akhirnya harus dibuat dengan trik mba nedha tulis di screen lalu khadijah disuruh menebak gimana bacanya. Alhamdulillah it's work! Khadijah akhirnya baca juga. Semoga Allah paring aman selamat lancar dan barokah, semangat focus for tilawati 2 ya pretty 🧏🏻‍♀️💖🙌🏻 | I383: 6281232193915
A384: February 26, 2025 1:32 pm | B384: 45713 | C384: =TEXT(B384, "mmmm") -> Februari | D384: 0.048611111 | E384: Millati-PWD | F384: Dehan-CND | G384: HADIR | H384: - Bacaan Ar Rum 16-24 > Alhamdulillah, bacaannya sudah semakin bagus. Ikhfa haqiqinya juga much better. Alhamdulillah. - Hafalan Surat Surat Al Adiyat Surat Al Humazah Surat At Takatsur Surat Al Fiil Surat Al Maun Rukun Islam& Rukun Iman > sebelumnya sudah dijelaskan soal rukun islam,tapi ternyata Dehan lupa. Akhirnya di review lagi. Alhamdulillah,sudah bisa jelasin kembali. Untuk rukun iman insyaallah Dehan paham. Makna k. Adab hal 9-10 Di hadits pertama menjelaskan tentang sabdanya nabi yang perintah untuk mencari teman yang berakhlaqul karimah. Di hadits kedua menjelaskan soal orang yang dicintai nabi dan akan dekat dengan nabi saat di hari kiamat nanti adalah orang yang berakhlak mulia. > Dehan bisa jelasin dengan benar yang hadits kedua, Alhamdulillah, insyaallah Dehan sudah faham. Notes: Jangan lupa homeworknya ya, Dehan. Baca surat ar rum 25-32. Sama hafalan surat al adiyat. amalsholih dilancarkan lagi yaa Semoga ilmu hari ini bisa bermanfaat dan barokah untuk Dehan.Aamiiin | I384: 6285707668655
A385: February 26, 2025 1:53 pm | B385: 45709 | C385: =TEXT(B385, "mmmm") -> Februari | D385: 0.04375 | E385: Nedha-PWD | F385: Fitri-CND | G385: HADIR | H385: Bacaan (-) *sedang haid Makna Kitabbusholah hal 146-147 (Bab mengajari/menuntun) Hadist. 1 Menjelaskan bahwasanya orang yang akan menemui ajalnya supaya dituntun dengan berucap kalimat 'la illa ha illallah' agar kelak bisa dimasukan ke dalam surga. Hadist. 2 Perintah nabi kepada umatnya sama halnya seperti hadist. 1 yaitu untuk menuntun orang yang mau mati dengan kalimat 'la illaha illallah' Alhamdulillah good, Fitri bisa mencerna dan memahami materi yang sudah disampaikan. Juga beberapa pertanyaan di berikan oleh Fitri that's good! Semoga Allah paring menjadi generus yang sholehah 💖 | I385: 6281232193915
A386: February 26, 2025 2:20 pm | B386: 45714 | C386: =TEXT(B386, "mmmm") -> Februari | D386: 0.05625 | E386: Millati-PWD | F386: Abell-NH | G386: HADIR | H386: Tilawati 3 page 31-32 > karena isi halamannya sedikit,jadi Abell baca 2 halaman. Alhamdulillah Abell bisa mengikuti dengan baik. Besok baca lagi di halaman 32 yaa, Abell Murajaah Surat Al Humazah Al Ashr > al humazah masih banyak yg lupa Doa-Doa Pagi sore Raja istighfar mencari ilmu Untuk kedua orang tua Mohon kesabaran Masuk rumah Asmaul Husna 1-40 > Alhamdulillah,mulai 21-30 sudah ada peningkatan, sudah lumayan lancar. Sekarang mulai menghafal 31-40 Rukun Islam > Abell bisa menyebutkan poin" rukun islam. Abell agak lupa di penjelasannya. Setelah dijelaskan, alhamdulilah Abell bisa jelasin balik. Subhanallah. Semoga ilmu yang didapat dari ngaji hari ini bisa bermanfaat dan barokah buat Abell. Aamiin | I386: 6285707668655
A387: February 26, 2025 10:06 pm | B387: 45707 | C387: =TEXT(B387, "mmmm") -> Februari | D387: 0.020833333 | E387: Fadly-SMG | F387: Mikail-CH | G387: HADIR | H387: Latihan nasehat | I387: 6281332534354
A388: February 26, 2025 10:07 pm | B388: 45708 | C388: =TEXT(B388, "mmmm") -> Februari | D388: 0.020833333 | E388: Fadly-SMG | F388: Mikail-CH | G388: HADIR | H388: Tilawatil 5 hal 27 | I388: 6281332534354
A389: February 26, 2025 10:08 pm | B389: 45709 | C389: =TEXT(B389, "mmmm") -> Februari | D389: 0.020833333 | E389: Fadly-SMG | F389: Mikail-CH | G389: HADIR | H389: - latihan nasehat - tilawati 5 hal 28 | I389: 6281332534354
...

Sheet Rekap Murid
A1: REKAPITULASI DURASI MENGAJI CABERAWIT & GENERUS US
B2: MULAI | C2: 44986 | D2: HINGGA | E2: 45016
A4: NO. | B4: NAMA MURID | C4: DURASI MENGAJI | D4: TARGET DURASI | E4: % DURASI | F4: JUMLAH PERTEMUAN | G4: RERATA DURASI / PERTEMUAN
A5: 1 | B5: AJ | C5: =sumifs('DATA MENTAH1'!$C$2:$C$1142,'DATA MENTAH1'!$B$2:$B$1142,">="&$C$2,'DATA MENTAH1'!$B$2:$B$1142,"<="&$E$2,'DATA MENTAH1'!$E$2:$E$1142,B5) -> #N/A | D5: 0.25 | E5: =IFERROR(C5/D5,0) -> 0 | F5: =COUNTIFS('DATA MENTAH1'!$E$2:$E$1118,B5,'DATA MENTAH1'!$B$2:$B$1118,">="&$C$2,'DATA MENTAH1'!$B$2:$B$1118,"<="&$E$2) -> 0 | G5: =IFERROR(C5/F5,0) -> 0
A6: 2 | B6: Dwiki | C6: =sumifs('DATA MENTAH1'!$C$2:$C$1142,'DATA MENTAH1'!$B$2:$B$1142,">="&$C$2,'DATA MENTAH1'!$B$2:$B$1142,"<="&$E$2,'DATA MENTAH1'!$E$2:$E$1142,B6) -> #N/A | D6: 0.25 | E6: =IFERROR(C6/D6,0) -> 0 | F6: =COUNTIFS('DATA MENTAH1'!$E$2:$E$1118,B6,'DATA MENTAH1'!$B$2:$B$1118,">="&$C$2,'DATA MENTAH1'!$B$2:$B$1118,"<="&$E$2) -> 0 | G6: =IFERROR(C6/F6,0) -> 0
A7: 3 | B7: Kizmira | C7: =sumifs('DATA MENTAH1'!$C$2:$C$1142,'DATA MENTAH1'!$B$2:$B$1142,">="&$C$2,'DATA MENTAH1'!$B$2:$B$1142,"<="&$E$2,'DATA MENTAH1'!$E$2:$E$1142,B7) -> #N/A | D7: 0.25 | E7: =IFERROR(C7/D7,0) -> 0 | F7: =COUNTIFS('DATA MENTAH1'!$E$2:$E$1118,B7,'DATA MENTAH1'!$B$2:$B$1118,">="&$C$2,'DATA MENTAH1'!$B$2:$B$1118,"<="&$E$2) -> 0 | G7: =IFERROR(C7/F7,0) -> 0
A8: 4 | B8: Kaisar | C8: =sumifs('DATA MENTAH1'!$C$2:$C$1142,'DATA MENTAH1'!$B$2:$B$1142,">="&$C$2,'DATA MENTAH1'!$B$2:$B$1142,"<="&$E$2,'DATA MENTAH1'!$E$2:$E$1142,B8) -> #N/A | D8: 0.25 | E8: =IFERROR(C8/D8,0) -> 0 | F8: =COUNTIFS('DATA MENTAH1'!$E$2:$E$1118,B8,'DATA MENTAH1'!$B$2:$B$1118,">="&$C$2,'DATA MENTAH1'!$B$2:$B$1118,"<="&$E$2) -> 0 | G8: =IFERROR(C8/F8,0) -> 0
A9: 5 | B9: Abi | C9: =sumifs('DATA MENTAH1'!$C$2:$C$1142,'DATA MENTAH1'!$B$2:$B$1142,">="&$C$2,'DATA MENTAH1'!$B$2:$B$1142,"<="&$E$2,'DATA MENTAH1'!$E$2:$E$1142,B9) -> #N/A | D9: 0.25 | E9: =IFERROR(C9/D9,0) -> 0 | F9: =COUNTIFS('DATA MENTAH1'!$E$2:$E$1118,B9,'DATA MENTAH1'!$B$2:$B$1118,">="&$C$2,'DATA MENTAH1'!$B$2:$B$1118,"<="&$E$2) -> 0 | G9: =IFERROR(C9/F9,0) -> 0
A10: 6 | B10: Dehan | C10: =sumifs('DATA MENTAH1'!$C$2:$C$1142,'DATA MENTAH1'!$B$2:$B$1142,">="&$C$2,'DATA MENTAH1'!$B$2:$B$1142,"<="&$E$2,'DATA MENTAH1'!$E$2:$E$1142,B10) -> #N/A | D10: 0.25 | E10: =IFERROR(C10/D10,0) -> 0 | F10: =COUNTIFS('DATA MENTAH1'!$E$2:$E$1118,B10,'DATA MENTAH1'!$B$2:$B$1118,">="&$C$2,'DATA MENTAH1'!$B$2:$B$1118,"<="&$E$2) -> 0 | G10: =IFERROR(C10/F10,0) -> 0
A11: 7 | B11: Chester | C11: =sumifs('DATA MENTAH1'!$C$2:$C$1142,'DATA MENTAH1'!$B$2:$B$1142,">="&$C$2,'DATA MENTAH1'!$B$2:$B$1142,"<="&$E$2,'DATA MENTAH1'!$E$2:$E$1142,B11) -> #N/A | D11: 0.125 | E11: =IFERROR(C11/D11,0) -> 0 | F11: =COUNTIFS('DATA MENTAH1'!$E$2:$E$1118,B11,'DATA MENTAH1'!$B$2:$B$1118,">="&$C$2,'DATA MENTAH1'!$B$2:$B$1118,"<="&$E$2) -> 0 | G11: =IFERROR(C11/F11,0) -> 0
A12: 8 | B12: Denissa | C12: =sumifs('DATA MENTAH1'!$C$2:$C$1142,'DATA MENTAH1'!$B$2:$B$1142,">="&$C$2,'DATA MENTAH1'!$B$2:$B$1142,"<="&$E$2,'DATA MENTAH1'!$E$2:$E$1142,B12) -> #N/A | D12: 0.25 | E12: =IFERROR(C12/D12,0) -> 0 | F12: =COUNTIFS('DATA MENTAH1'!$E$2:$E$1118,B12,'DATA MENTAH1'!$B$2:$B$1118,">="&$C$2,'DATA MENTAH1'!$B$2:$B$1118,"<="&$E$2) -> 0 | G12: =IFERROR(C12/F12,0) -> 0
A13: 9 | B13: Kayla | C13: =sumifs('DATA MENTAH1'!$C$2:$C$1142,'DATA MENTAH1'!$B$2:$B$1142,">="&$C$2,'DATA MENTAH1'!$B$2:$B$1142,"<="&$E$2,'DATA MENTAH1'!$E$2:$E$1142,B13) -> #N/A | D13: 0.083333333 | E13: =IFERROR(C13/D13,0) -> 0 | F13: =COUNTIFS('DATA MENTAH1'!$E$2:$E$1118,B13,'DATA MENTAH1'!$B$2:$B$1118,">="&$C$2,'DATA MENTAH1'!$B$2:$B$1118,"<="&$E$2) -> 0 | G13: =IFERROR(C13/F13,0) -> 0
A14: 10 | B14: Grazia | C14: =sumifs('DATA MENTAH1'!$C$2:$C$1142,'DATA MENTAH1'!$B$2:$B$1142,">="&$C$2,'DATA MENTAH1'!$B$2:$B$1142,"<="&$E$2,'DATA MENTAH1'!$E$2:$E$1142,B14) -> #N/A | D14: 0.25 | E14: =IFERROR(C14/D14,0) -> 0 | F14: =COUNTIFS('DATA MENTAH1'!$E$2:$E$1118,B14,'DATA MENTAH1'!$B$2:$B$1118,">="&$C$2,'DATA MENTAH1'!$B$2:$B$1118,"<="&$E$2) -> 0 | G14: =IFERROR(C14/F14,0) -> 0
A15: 11 | B15: Qalesya | C15: =sumifs('DATA MENTAH1'!$C$2:$C$1142,'DATA MENTAH1'!$B$2:$B$1142,">="&$C$2,'DATA MENTAH1'!$B$2:$B$1142,"<="&$E$2,'DATA MENTAH1'!$E$2:$E$1142,B15) -> #N/A | D15: 0.25 | E15: =IFERROR(C15/D15,0) -> 0 | F15: =COUNTIFS('DATA MENTAH1'!$E$2:$E$1118,B15,'DATA MENTAH1'!$B$2:$B$1118,">="&$C$2,'DATA MENTAH1'!$B$2:$B$1118,"<="&$E$2) -> 0 | G15: =IFERROR(C15/F15,0) -> 0
A16: 12 | B16: Kirana | C16: =sumifs('DATA MENTAH1'!$C$2:$C$1142,'DATA MENTAH1'!$B$2:$B$1142,">="&$C$2,'DATA MENTAH1'!$B$2:$B$1142,"<="&$E$2,'DATA MENTAH1'!$E$2:$E$1142,B16) -> #N/A | D16: 0.25 | E16: =IFERROR(C16/D16,0) -> 0 | F16: =COUNTIFS('DATA MENTAH1'!$E$2:$E$1118,B16,'DATA MENTAH1'!$B$2:$B$1118,">="&$C$2,'DATA MENTAH1'!$B$2:$B$1118,"<="&$E$2) -> 0 | G16: =IFERROR(C16/F16,0) -> 0
... A19: 15 | B19: Jourdan | C19: =sumifs('DATA MENTAH1'!$C$2:$C$1142,'DATA MENTAH1'!$B$2:$B$1142,">="&$C$2,'DATA MENTAH1'!$B$2:$B$1142,"<="&$E$2,'DATA MENTAH1'!$E$2:$E$1142,B19) -> #N/A | D19: 0.25 | E19: =IFERROR(C19/D19,0) -> 0 | F19: =COUNTIFS('DATA MENTAH1'!$E$2:$E$1118,B19,'DATA MENTAH1'!$B$2:$B$1118,">="&$C$2,'DATA MENTAH1'!$B$2:$B$1118,"<="&$E$2) -> 0 | G19: =IFERROR(C19/F19,0) -> 0
A20: 16 | B20: Jagis | C20: =sumifs('DATA MENTAH1'!$C$2:$C$1142,'DATA MENTAH1'!$B$2:$B$1142,">="&$C$2,'DATA MENTAH1'!$B$2:$B$1142,"<="&$E$2,'DATA MENTAH1'!$E$2:$E$1142,B20) -> #N/A | E20: =IFERROR(C20/D20,0) -> 0 | F20: =COUNTIFS('DATA MENTAH1'!$E$2:$E$1118,B20,'DATA MENTAH1'!$B$2:$B$1118,">="&$C$2,'DATA MENTAH1'!$B$2:$B$1118,"<="&$E$2) -> 0 | G20: =IFERROR(C20/F20,0) -> 0
A21: 17 | B21: Jubilee | C21: =sumifs('DATA MENTAH1'!$C$2:$C$1142,'DATA MENTAH1'!$B$2:$B$1142,">="&$C$2,'DATA MENTAH1'!$B$2:$B$1142,"<="&$E$2,'DATA MENTAH1'!$E$2:$E$1142,B21) -> #N/A | D21: 0.25 | E21: =IFERROR(C21/D21,0) -> 0 | F21: =COUNTIFS('DATA MENTAH1'!$E$2:$E$1118,B21,'DATA MENTAH1'!$B$2:$B$1118,">="&$C$2,'DATA MENTAH1'!$B$2:$B$1118,"<="&$E$2) -> 0 | G21: =IFERROR(C21/F21,0) -> 0
A22: 18 | B22: Gabriel | C22: =sumifs('DATA MENTAH1'!$C$2:$C$1142,'DATA MENTAH1'!$B$2:$B$1142,">="&$C$2,'DATA MENTAH1'!$B$2:$B$1142,"<="&$E$2,'DATA MENTAH1'!$E$2:$E$1142,B22) -> #N/A | E22: =IFERROR(C22/D22,0) -> 0 | F22: =COUNTIFS('DATA MENTAH1'!$E$2:$E$1118,B22,'DATA MENTAH1'!$B$2:$B$1118,">="&$C$2,'DATA MENTAH1'!$B$2:$B$1118,"<="&$E$2) -> 0 | G22: =IFERROR(C22/F22,0) -> 0
A23: 19 | B23: Fitri | C23: =sumifs('DATA MENTAH1'!$C$2:$C$1142,'DATA MENTAH1'!$B$2:$B$1142,">="&$C$2,'DATA MENTAH1'!$B$2:$B$1142,"<="&$E$2,'DATA MENTAH1'!$E$2:$E$1142,B23) -> #N/A | E23: =IFERROR(C23/D23,0) -> 0 | F23: =COUNTIFS('DATA MENTAH1'!$E$2:$E$1118,B23,'DATA MENTAH1'!$B$2:$B$1118,">="&$C$2,'DATA MENTAH1'!$B$2:$B$1118,"<="&$E$2) -> 0 | G23: =IFERROR(C23/F23,0) -> 0
A24: 20 | B24: Irsan | C24: =sumifs('DATA MENTAH1'!$C$2:$C$1142,'DATA MENTAH1'!$B$2:$B$1142,">="&$C$2,'DATA MENTAH1'!$B$2:$B$1142,"<="&$E$2,'DATA MENTAH1'!$E$2:$E$1142,B24) -> #N/A | E24: =IFERROR(C24/D24,0) -> 0 | F24: =COUNTIFS('DATA MENTAH1'!$E$2:$E$1118,B24,'DATA MENTAH1'!$B$2:$B$1118,">="&$C$2,'DATA MENTAH1'!$B$2:$B$1118,"<="&$E$2) -> 0 | G24: =IFERROR(C24/F24,0) -> 0
A25: 21 | B25: Tami | C25: =sumifs('DATA MENTAH1'!$C$2:$C$1142,'DATA MENTAH1'!$B$2:$B$1142,">="&$C$2,'DATA MENTAH1'!$B$2:$B$1142,"<="&$E$2,'DATA MENTAH1'!$E$2:$E$1142,B25) -> #N/A | D25: 0.25 | E25: =IFERROR(C25/D25,0) -> 0 | F25: =COUNTIFS('DATA MENTAH1'!$E$2:$E$1118,B25,'DATA MENTAH1'!$B$2:$B$1118,">="&$C$2,'DATA MENTAH1'!$B$2:$B$1118,"<="&$E$2) -> 0 | G25: =IFERROR(C25/F25,0) -> 0
A26: 22 | B26: Khairuna | C26: =sumifs('DATA MENTAH1'!$C$2:$C$1142,'DATA MENTAH1'!$B$2:$B$1142,">="&$C$2,'DATA MENTAH1'!$B$2:$B$1142,"<="&$E$2,'DATA MENTAH1'!$E$2:$E$1142,B26) -> #N/A | D26: 0.25 | E26: =IFERROR(C26/D26,0) -> 0 | F26: =COUNTIFS('DATA MENTAH1'!$E$2:$E$1118,B26,'DATA MENTAH1'!$B$2:$B$1118,">="&$C$2,'DATA MENTAH1'!$B$2:$B$1118,"<="&$E$2) -> 0 | G26: =IFERROR(C26/F26,0) -> 0
A27: 23 | B27: Nadine | C27: =sumifs('DATA MENTAH1'!$C$2:$C$1142,'DATA MENTAH1'!$B$2:$B$1142,">="&$C$2,'DATA MENTAH1'!$B$2:$B$1142,"<="&$E$2,'DATA MENTAH1'!$E$2:$E$1142,B27) -> #N/A | E27: =IFERROR(C27/D27,0) -> 0 | F27: =COUNTIFS('DATA MENTAH1'!$E$2:$E$1118,B27,'DATA MENTAH1'!$B$2:$B$1118,">="&$C$2,'DATA MENTAH1'!$B$2:$B$1118,"<="&$E$2) -> 0 | G27: =IFERROR(C27/F27,0) -> 0
A28: 24 | B28: Dinda & Daud | C28: =sumifs('DATA MENTAH1'!$C$2:$C$1142,'DATA MENTAH1'!$B$2:$B$1142,">="&$C$2,'DATA MENTAH1'!$B$2:$B$1142,"<="&$E$2,'DATA MENTAH1'!$E$2:$E$1142,B28) -> #N/A | E28: =IFERROR(C28/D28,0) -> 0 | F28: =COUNTIFS('DATA MENTAH1'!$E$2:$E$1118,B28,'DATA MENTAH1'!$B$2:$B$1118,">="&$C$2,'DATA MENTAH1'!$B$2:$B$1118,"<="&$E$2) -> 0 | G28: =IFERROR(C28/F28,0) -> 0

Sheet Januari
A1: REKAPITULASI KEHADIRAN MURID PENGAJIAN PPG AMERICA
B2: Mulai : | C2: 45658 | D2: Hingga : | E2: 45688
A4: NO. | B4: NAMA MURID | C4: KELOMPOK | D4: Jenjang Usia | E4: DURASI MENGAJI | F4: TARGET DURASI | G4: % DURASI | H4: HADIR | I4: BY VN | J4: IZIN (MURID)
A5: 1 | B5: Abell-NH | C5: New Hampshire | D5: PraCBR-CBR | E5: =sumifs('KEG. PENGAJIAN HARIAN'!$D$2:$D968,'KEG. PENGAJIAN HARIAN'!$B$2:$B968,">="&$C$2,'KEG. PENGAJIAN HARIAN'!$B$2:$B968,"<="&$E$2,'KEG. PENGAJIAN HARIAN'!$F$2:$F968,B5) -> 0.27986111 | F5: 0.5 | G5: =IFERROR(E5/F5,0) -> 0.55972222 | H5: =COUNTIFS('KEG. PENGAJIAN HARIAN'!$F$2:$F968,B5,'KEG. PENGAJIAN HARIAN'!$B$2:$B968,">="&$C$2,'KEG. PENGAJIAN HARIAN'!$B$2:$B968,"<="&$E$2,'KEG. PENGAJIAN HARIAN'!$G$2:$G968,"hadir") -> 5 | I5: =COUNTIFS('KEG. PENGAJIAN HARIAN'!$F$2:$F968,B5,'KEG. PENGAJIAN HARIAN'!$B$2:$B968,">="&$C$2,'KEG. PENGAJIAN HARIAN'!$B$2:$B968,"<="&$E$2,'KEG. PENGAJIAN HARIAN'!$G$2:$G968,"By VN") -> 0 | J5: =COUNTIFS('KEG. PENGAJIAN HARIAN'!$F$2:$F968,B5,'KEG. PENGAJIAN HARIAN'!$B$2:$B968,">="&$C$2,'KEG. PENGAJIAN HARIAN'!$B$2:$B968,"<="&$E$2,'KEG. PENGAJIAN HARIAN'!$G$2:$G968,"izin (murid)") -> 0
A6: 2 | B6: Abi-BFL | C6: Chicago | D6: PraNikah | E6: =sumifs('KEG. PENGAJIAN HARIAN'!$D$2:$D968,'KEG. PENGAJIAN HARIAN'!$B$2:$B968,">="&$C$2,'KEG. PENGAJIAN HARIAN'!$B$2:$B968,"<="&$E$2,'KEG. PENGAJIAN HARIAN'!$F$2:$F968,B6) -> 0.28472222 | F6: 0.5 | G6: =IFERROR(E6/F6,0) -> 0.56944444 | H6: =COUNTIFS('KEG. PENGAJIAN HARIAN'!$F$2:$F968,B6,'KEG. PENGAJIAN HARIAN'!$B$2:$B968,">="&$C$2,'KEG. PENGAJIAN HARIAN'!$B$2:$B968,"<="&$E$2,'KEG. PENGAJIAN HARIAN'!$G$2:$G968,"hadir") -> 6 | I6: =COUNTIFS('KEG. PENGAJIAN HARIAN'!$F$2:$F968,B6,'KEG. PENGAJIAN HARIAN'!$B$2:$B968,">="&$C$2,'KEG. PENGAJIAN HARIAN'!$B$2:$B968,"<="&$E$2,'KEG. PENGAJIAN HARIAN'!$G$2:$G968,"By VN") -> 0 | J6: =COUNTIFS('KEG. PENGAJIAN HARIAN'!$F$2:$F968,B6,'KEG. PENGAJIAN HARIAN'!$B$2:$B968,">="&$C$2,'KEG. PENGAJIAN HARIAN'!$B$2:$B968,"<="&$E$2,'KEG. PENGAJIAN HARIAN'!$G$2:$G968,"izin (murid)") -> 0
A7: 3 | B7: Cheryl-NH | C7: New Hampshire | D7: PraCBR-CBR | E7: =sumifs('KEG. PENGAJIAN HARIAN'!$D$2:$D968,'KEG. PENGAJIAN HARIAN'!$B$2:$B968,">="&$C$2,'KEG. PENGAJIAN HARIAN'!$B$2:$B968,"<="&$E$2,'KEG. PENGAJIAN HARIAN'!$F$2:$F968,B7) -> 0.14305556 | F7: 0.5 | G7: =IFERROR(E7/F7,0) -> 0.28611111 | H7: =COUNTIFS('KEG. PENGAJIAN HARIAN'!$F$2:$F968,B7,'KEG. PENGAJIAN HARIAN'!$B$2:$B968,">="&$C$2,'KEG. PENGAJIAN HARIAN'!$B$2:$B968,"<="&$E$2,'KEG. PENGAJIAN HARIAN'!$G$2:$G968,"hadir") -> 4 | I7: =COUNTIFS('KEG. PENGAJIAN HARIAN'!$F$2:$F968,B7,'KEG. PENGAJIAN HARIAN'!$B$2:$B968,">="&$C$2,'KEG. PENGAJIAN HARIAN'!$B$2:$B968,"<="&$E$2,'KEG. PENGAJIAN HARIAN'!$G$2:$G968,"By VN") -> 0 | J7: =COUNTIFS('KEG. PENGAJIAN HARIAN'!$F$2:$F968,B7,'KEG. PENGAJIAN HARIAN'!$B$2:$B968,">="&$C$2,'KEG. PENGAJIAN HARIAN'!$B$2:$B968,"<="&$E$2,'KEG. PENGAJIAN HARIAN'!$G$2:$G968,"izin (murid)") -> 3 | K7: PraCBR-CBR | L7: =countif(D5:D32,"PraCBR-CBR") -> 16
A8: 4 | B8: Chester-PD | C8: New Hampshire | D8: PraCBR-CBR | E8: =sumifs('KEG. PENGAJIAN HARIAN'!$D$2:$D968,'KEG. PENGAJIAN HARIAN'!$B$2:$B968,">="&$C$2,'KEG. PENGAJIAN HARIAN'!$B$2:$B968,"<="&$E$2,'KEG. PENGAJIAN HARIAN'!$F$2:$F968,B8) -> 0.46388889 | F8: 0.5 | G8: =IFERROR(E8/F8,0) -> 0.92777778 | H8: =COUNTIFS('KEG. PENGAJIAN HARIAN'!$F$2:$F968,B8,'KEG. PENGAJIAN HARIAN'!$B$2:$B968,">="&$C$2,'KEG. PENGAJIAN HARIAN'!$B$2:$B968,"<="&$E$2,'KEG. PENGAJIAN HARIAN'!$G$2:$G968,"hadir") -> 11 | I8: =COUNTIFS('KEG. PENGAJIAN HARIAN'!$F$2:$F968,B8,'KEG. PENGAJIAN HARIAN'!$B$2:$B968,">="&$C$2,'KEG. PENGAJIAN HARIAN'!$B$2:$B968,"<="&$E$2,'KEG. PENGAJIAN HARIAN'!$G$2:$G968,"By VN") -> 0 | J8: =COUNTIFS('KEG. PENGAJIAN HARIAN'!$F$2:$F968,B8,'KEG. PENGAJIAN HARIAN'!$B$2:$B968,">="&$C$2,'KEG. PENGAJIAN HARIAN'!$B$2:$B968,"<="&$E$2,'KEG. PENGAJIAN HARIAN'!$G$2:$G968,"izin (murid)") -> 0 | K8: PraRMJ-RMJ | L8: =countif(D5:D32,"PraRMJ-RMJ") -> 6
A9: 5 | B9: Dawud-RLG | C9: New Hampshire | D9: PraCBR-CBR | E9: =sumifs('KEG. PENGAJIAN HARIAN'!$D$2:$D968,'KEG. PENGAJIAN HARIAN'!$B$2:$B968,">="&$C$2,'KEG. PENGAJIAN HARIAN'!$B$2:$B968,"<="&$E$2,'KEG. PENGAJIAN HARIAN'!$F$2:$F968,B9) -> 0.48125 | F9: 0.5 | G9: =IFERROR(E9/F9,0) -> 0.9625 | H9: =COUNTIFS('KEG. PENGAJIAN HARIAN'!$F$2:$F968,B9,'KEG. PENGAJIAN HARIAN'!$B$2:$B968,">="&$C$2,'KEG. PENGAJIAN HARIAN'!$B$2:$B968,"<="&$E$2,'KEG. PENGAJIAN HARIAN'!$G$2:$G968,"hadir") -> 12 | I9: =COUNTIFS('KEG. PENGAJIAN HARIAN'!$F$2:$F968,B9,'KEG. PENGAJIAN HARIAN'!$B$2:$B968,">="&$C$2,'KEG. PENGAJIAN HARIAN'!$B$2:$B968,"<="&$E$2,'KEG. PENGAJIAN HARIAN'!$G$2:$G968,"By VN") -> 0 | J9: =COUNTIFS('KEG. PENGAJIAN HARIAN'!$F$2:$F968,B9,'KEG. PENGAJIAN HARIAN'!$B$2:$B968,">="&$C$2,'KEG. PENGAJIAN HARIAN'!$B$2:$B968,"<="&$E$2,'KEG. PENGAJIAN HARIAN'!$G$2:$G968,"izin (murid)") -> 0 | K9: PraNIkah | L9: =countif(D5:D32,"PraNikah") -> 6
A10: 6 | B10: Dehan-CND | C10: Canada | D10: PraRMJ-RMJ | E10: =sumifs('KEG. PENGAJIAN HARIAN'!$D$2:$D968,'KEG. PENGAJIAN HARIAN'!$B$2:$B968,">="&$C$2,'KEG. PENGAJIAN HARIAN'!$B$2:$B968,"<="&$E$2,'KEG. PENGAJIAN HARIAN'!$F$2:$F968,B10) -> 0.32777778 | F10: 0.5 | G10: =IFERROR(E10/F10,0) -> 0.65555556 | H10: =COUNTIFS('KEG. PENGAJIAN HARIAN'!$F$2:$F968,B10,'KEG. PENGAJIAN HARIAN'!$B$2:$B968,">="&$C$2,'KEG. PENGAJIAN HARIAN'!$B$2:$B968,"<="&$E$2,'KEG. PENGAJIAN HARIAN'!$G$2:$G968,"hadir") -> 8 | I10: =COUNTIFS('KEG. PENGAJIAN HARIAN'!$F$2:$F968,B10,'KEG. PENGAJIAN HARIAN'!$B$2:$B968,">="&$C$2,'KEG. PENGAJIAN HARIAN'!$B$2:$B968,"<="&$E$2,'KEG. PENGAJIAN HARIAN'!$G$2:$G968,"By VN") -> 0 | J10: =COUNTIFS('KEG. PENGAJIAN HARIAN'!$F$2:$F968,B10,'KEG. PENGAJIAN HARIAN'!$B$2:$B968,">="&$C$2,'KEG. PENGAJIAN HARIAN'!$B$2:$B968,"<="&$E$2,'KEG. PENGAJIAN HARIAN'!$G$2:$G968,"izin (murid)") -> 0 | L10: =sum(L7:L9) -> 28
A11: 7 | B11: Denissa-RLG | C11: New Hampshire | D11: PraRMJ-RMJ | E11: =sumifs('KEG. PENGAJIAN HARIAN'!$D$2:$D968,'KEG. PENGAJIAN HARIAN'!$B$2:$B968,">="&$C$2,'KEG. PENGAJIAN HARIAN'!$B$2:$B968,"<="&$E$2,'KEG. PENGAJIAN HARIAN'!$F$2:$F968,B11) -> 0.12222222 | F11: 0.5 | G11: =IFERROR(E11/F11,0) -> 0.24444444 | H11: =COUNTIFS('KEG. PENGAJIAN HARIAN'!$F$2:$F968,B11,'KEG. PENGAJIAN HARIAN'!$B$2:$B968,">="&$C$2,'KEG. PENGAJIAN HARIAN'!$B$2:$B968,"<="&$E$2,'KEG. PENGAJIAN HARIAN'!$G$2:$G968,"hadir") -> 3 | I11: =COUNTIFS('KEG. PENGAJIAN HARIAN'!$F$2:$F968,B11,'KEG. PENGAJIAN HARIAN'!$B$2:$B968,">="&$C$2,'KEG. PENGAJIAN HARIAN'!$B$2:$B968,"<="&$E$2,'KEG. PENGAJIAN HARIAN'!$G$2:$G968,"By VN") -> 1 | J11: =COUNTIFS('KEG. PENGAJIAN HARIAN'!$F$2:$F968,B11,'KEG. PENGAJIAN HARIAN'!$B$2:$B968,">="&$C$2,'KEG. PENGAJIAN HARIAN'!$B$2:$B968,"<="&$E$2,'KEG. PENGAJIAN HARIAN'!$G$2:$G968,"izin (murid)") -> 3
A12: 8 | B12: Dinda-RLG | C12: New Hampshire | D12: PraCBR-CBR | E12: =sumifs('KEG. PENGAJIAN HARIAN'!$D$2:$D968,'KEG. PENGAJIAN HARIAN'!$B$2:$B968,">="&$C$2,'KEG. PENGAJIAN HARIAN'!$B$2:$B968,"<="&$E$2,'KEG. PENGAJIAN HARIAN'!$F$2:$F968,B12) -> 0.23680556 | F12: 0.5 | G12: =IFERROR(E12/F12,0) -> 0.47361111 | H12: =COUNTIFS('KEG. PENGAJIAN HARIAN'!$F$2:$F968,B12,'KEG. PENGAJIAN HARIAN'!$B$2:$B968,">="&$C$2,'KEG. PENGAJIAN HARIAN'!$B$2:$B968,"<="&$E$2,'KEG. PENGAJIAN HARIAN'!$G$2:$G968,"hadir") -> 6 | I12: =COUNTIFS('KEG. PENGAJIAN HARIAN'!$F$2:$F968,B12,'KEG. PENGAJIAN HARIAN'!$B$2:$B968,">="&$C$2,'KEG. PENGAJIAN HARIAN'!$B$2:$B968,"<="&$E$2,'KEG. PENGAJIAN HARIAN'!$G$2:$G968,"By VN") -> 0 | J12: =COUNTIFS('KEG. PENGAJIAN HARIAN'!$F$2:$F968,B12,'KEG. PENGAJIAN HARIAN'!$B$2:$B968,">="&$C$2,'KEG. PENGAJIAN HARIAN'!$B$2:$B968,"<="&$E$2,'KEG. PENGAJIAN HARIAN'!$G$2:$G968,"izin (murid)") -> 0
A13: 9 | B13: Dwiki-RLG | C13: New Hampshire | D13: PraNikah | E13: =sumifs('KEG. PENGAJIAN HARIAN'!$D$2:$D968,'KEG. PENGAJIAN HARIAN'!$B$2:$B968,">="&$C$2,'KEG. PENGAJIAN HARIAN'!$B$2:$B968,"<="&$E$2,'KEG. PENGAJIAN HARIAN'!$F$2:$F968,B13) -> 0.33680556 | F13: 0.5 | G13: =IFERROR(E13/F13,0) -> 0.67361111 | H13: =COUNTIFS('KEG. PENGAJIAN HARIAN'!$F$2:$F968,B13,'KEG. PENGAJIAN HARIAN'!$B$2:$B968,">="&$C$2,'KEG. PENGAJIAN HARIAN'!$B$2:$B968,"<="&$E$2,'KEG. PENGAJIAN HARIAN'!$G$2:$G968,"hadir") -> 10 | I13: =COUNTIFS('KEG. PENGAJIAN HARIAN'!$F$2:$F968,B13,'KEG. PENGAJIAN HARIAN'!$B$2:$B968,">="&$C$2,'KEG. PENGAJIAN HARIAN'!$B$2:$B968,"<="&$E$2,'KEG. PENGAJIAN HARIAN'!$G$2:$G968,"By VN") -> 0 | J13: =COUNTIFS('KEG. PENGAJIAN HARIAN'!$F$2:$F968,B13,'KEG. PENGAJIAN HARIAN'!$B$2:$B968,">="&$C$2,'KEG. PENGAJIAN HARIAN'!$B$2:$B968,"<="&$E$2,'KEG. PENGAJIAN HARIAN'!$G$2:$G968,"izin (murid)") -> 0
A14: 10 | B14: Dylan-CA | C14: California | D14: PraRMJ-RMJ | E14: =sumifs('KEG. PENGAJIAN HARIAN'!$D$2:$D968,'KEG. PENGAJIAN HARIAN'!$B$2:$B968,">="&$C$2,'KEG. PENGAJIAN HARIAN'!$B$2:$B968,"<="&$E$2,'KEG. PENGAJIAN HARIAN'!$F$2:$F968,B14) -> 0.26180556 | F14: 0.5 | G14: =IFERROR(E14/F14,0) -> 0.52361111 | H14: =COUNTIFS('KEG. PENGAJIAN HARIAN'!$F$2:$F968,B14,'KEG. PENGAJIAN HARIAN'!$B$2:$B968,">="&$C$2,'KEG. PENGAJIAN HARIAN'!$B$2:$B968,"<="&$E$2,'KEG. PENGAJIAN HARIAN'!$G$2:$G968,"hadir") -> 8 | I14: =COUNTIFS('KEG. PENGAJIAN HARIAN'!$F$2:$F968,B14,'KEG. PENGAJIAN HARIAN'!$B$2:$B968,">="&$C$2,'KEG. PENGAJIAN HARIAN'!$B$2:$B968,"<="&$E$2,'KEG. PENGAJIAN HARIAN'!$G$2:$G968,"By VN") -> 0 | J14: =COUNTIFS('KEG. PENGAJIAN HARIAN'!$F$2:$F968,B14,'KEG. PENGAJIAN HARIAN'!$B$2:$B968,">="&$C$2,'KEG. PENGAJIAN HARIAN'!$B$2:$B968,"<="&$E$2,'KEG. PENGAJIAN HARIAN'!$G$2:$G968,"izin (murid)") -> 1
A15: 11 | B15: Fitri-CND | C15: Canada | D15: PraRMJ-RMJ | E15: =sumifs('KEG. PENGAJIAN HARIAN'!$D$2:$D968,'KEG. PENGAJIAN HARIAN'!$B$2:$B968,">="&$C$2,'KEG. PENGAJIAN HARIAN'!$B$2:$B968,"<="&$E$2,'KEG. PENGAJIAN HARIAN'!$F$2:$F968,B15) -> 0.22430556 | F15: 0.5 | G15: =IFERROR(E15/F15,0) -> 0.44861111 | H15: =COUNTIFS('KEG. PENGAJIAN HARIAN'!$F$2:$F968,B15,'KEG. PENGAJIAN HARIAN'!$B$2:$B968,">="&$C$2,'KEG. PENGAJIAN HARIAN'!$B$2:$B968,"<="&$E$2,'KEG. PENGAJIAN HARIAN'!$G$2:$G968,"hadir") -> 5 | I15: =COUNTIFS('KEG. PENGAJIAN HARIAN'!$F$2:$F968,B15,'KEG. PENGAJIAN HARIAN'!$B$2:$B968,">="&$C$2,'KEG. PENGAJIAN HARIAN'!$B$2:$B968,"<="&$E$2,'KEG. PENGAJIAN HARIAN'!$G$2:$G968,"By VN") -> 0 | J15: =COUNTIFS('KEG. PENGAJIAN HARIAN'!$F$2:$F968,B15,'KEG. PENGAJIAN HARIAN'!$B$2:$B968,">="&$C$2,'KEG. PENGAJIAN HARIAN'!$B$2:$B968,"<="&$E$2,'KEG. PENGAJIAN HARIAN'!$G$2:$G968,"izin (murid)") -> 0
A16: 12 | B16: Gabriel-CH | C16: Chicago | D16: PraCBR-CBR | E16: =sumifs('KEG. PENGAJIAN HARIAN'!$D$2:$D968,'KEG. PENGAJIAN HARIAN'!$B$2:$B968,">="&$C$2,'KEG. PENGAJIAN HARIAN'!$B$2:$B968,"<="&$E$2,'KEG. PENGAJIAN HARIAN'!$F$2:$F968,B16) -> 0.31388889 | F16: 0.5 | G16: =IFERROR(E16/F16,0) -> 0.62777778 | H16: =COUNTIFS('KEG. PENGAJIAN HARIAN'!$F$2:$F968,B16,'KEG. PENGAJIAN HARIAN'!$B$2:$B968,">="&$C$2,'KEG. PENGAJIAN HARIAN'!$B$2:$B968,"<="&$E$2,'KEG. PENGAJIAN HARIAN'!$G$2:$G968,"hadir") -> 14 | I16: =COUNTIFS('KEG. PENGAJIAN HARIAN'!$F$2:$F968,B16,'KEG. PENGAJIAN HARIAN'!$B$2:$B968,">="&$C$2,'KEG. PENGAJIAN HARIAN'!$B$2:$B968,"<="&$E$2,'KEG. PENGAJIAN HARIAN'!$G$2:$G968,"By VN") -> 0 | J16: =COUNTIFS('KEG. PENGAJIAN HARIAN'!$F$2:$F968,B16,'KEG. PENGAJIAN HARIAN'!$B$2:$B968,">="&$C$2,'KEG. PENGAJIAN HARIAN'!$B$2:$B968,"<="&$E$2,'KEG. PENGAJIAN HARIAN'!$G$2:$G968,"izin (murid)") -> 0
A17: 13 | B17: Grazia-IN | C17: Chicago | D17: PraCBR-CBR | E17: =sumifs('KEG. PENGAJIAN HARIAN'!$D$2:$D968,'KEG. PENGAJIAN HARIAN'!$B$2:$B968,">="&$C$2,'KEG. PENGAJIAN HARIAN'!$B$2:$B968,"<="&$E$2,'KEG. PENGAJIAN HARIAN'!$F$2:$F968,B17) -> 0.43472222 | F17: 0.5 | G17: =IFERROR(E17/F17,0) -> 0.86944444 | H17: =COUNTIFS('KEG. PENGAJIAN HARIAN'!$F$2:$F968,B17,'KEG. PENGAJIAN HARIAN'!$B$2:$B968,">="&$C$2,'KEG. PENGAJIAN HARIAN'!$B$2:$B968,"<="&$E$2,'KEG. PENGAJIAN HARIAN'!$G$2:$G968,"hadir") -> 12 | I17: =COUNTIFS('KEG. PENGAJIAN HARIAN'!$F$2:$F968,B17,'KEG. PENGAJIAN HARIAN'!$B$2:$B968,">="&$C$2,'KEG. PENGAJIAN HARIAN'!$B$2:$B968,"<="&$E$2,'KEG. PENGAJIAN HARIAN'!$G$2:$G968,"By VN") -> 0 | J17: =COUNTIFS('KEG. PENGAJIAN HARIAN'!$F$2:$F968,B17,'KEG. PENGAJIAN HARIAN'!$B$2:$B968,">="&$C$2,'KEG. PENGAJIAN HARIAN'!$B$2:$B968,"<="&$E$2,'KEG. PENGAJIAN HARIAN'!$G$2:$G968,"izin (murid)") -> 0
A18: 14 | B18: Hafiz-PTM | C18: New Hampshire | D18: PraCBR-CBR | E18: =sumifs('KEG. PENGAJIAN HARIAN'!$D$2:$D968,'KEG. PENGAJIAN HARIAN'!$B$2:$B968,">="&$C$2,'KEG. PENGAJIAN HARIAN'!$B$2:$B968,"<="&$E$2,'KEG. PENGAJIAN HARIAN'!$F$2:$F968,B18) -> 0.47569444 | F18: 0.5 | G18: =IFERROR(E18/F18,0) -> 0.95138889 | H18: =COUNTIFS('KEG. PENGAJIAN HARIAN'!$F$2:$F968,B18,'KEG. PENGAJIAN HARIAN'!$B$2:$B968,">="&$C$2,'KEG. PENGAJIAN HARIAN'!$B$2:$B968,"<="&$E$2,'KEG. PENGAJIAN HARIAN'!$G$2:$G968,"hadir") -> 13 | I18: =COUNTIFS('KEG. PENGAJIAN HARIAN'!$F$2:$F968,B18,'KEG. PENGAJIAN HARIAN'!$B$2:$B968,">="&$C$2,'KEG. PENGAJIAN HARIAN'!$B$2:$B968,"<="&$E$2,'KEG. PENGAJIAN HARIAN'!$G$2:$G968,"By VN") -> 0 | J18: =COUNTIFS('KEG. PENGAJIAN HARIAN'!$F$2:$F968,B18,'KEG. PENGAJIAN HARIAN'!$B$2:$B968,">="&$C$2,'KEG. PENGAJIAN HARIAN'!$B$2:$B968,"<="&$E$2,'KEG. PENGAJIAN HARIAN'!$G$2:$G968,"izin (murid)") -> 2
A19: 15 | B19: Irsan-CH | C19: Chicago | D19: PraRMJ-RMJ | E19: =sumifs('KEG. PENGAJIAN HARIAN'!$D$2:$D968,'KEG. PENGAJIAN HARIAN'!$B$2:$B968,">="&$C$2,'KEG. PENGAJIAN HARIAN'!$B$2:$B968,"<="&$E$2,'KEG. PENGAJIAN HARIAN'!$F$2:$F968,B19) -> 0.28958333 | F19: 0.5 | G19: =IFERROR(E19/F19,0) -> 0.57916667 | H19: =COUNTIFS('KEG. PENGAJIAN HARIAN'!$F$2:$F968,B19,'KEG. PENGAJIAN HARIAN'!$B$2:$B968,">="&$C$2,'KEG. PENGAJIAN HARIAN'!$B$2:$B968,"<="&$E$2,'KEG. PENGAJIAN HARIAN'!$G$2:$G968,"hadir") -> 8 | I19: =COUNTIFS('KEG. PENGAJIAN HARIAN'!$F$2:$F968,B19,'KEG. PENGAJIAN HARIAN'!$B$2:$B968,">="&$C$2,'KEG. PENGAJIAN HARIAN'!$B$2:$B968,"<="&$E$2,'KEG. PENGAJIAN HARIAN'!$G$2:$G968,"By VN") -> 0 | J19: =COUNTIFS('KEG. PENGAJIAN HARIAN'!$F$2:$F968,B19,'KEG. PENGAJIAN HARIAN'!$B$2:$B968,">="&$C$2,'KEG. PENGAJIAN HARIAN'!$B$2:$B968,"<="&$E$2,'KEG. PENGAJIAN HARIAN'!$G$2:$G968,"izin (murid)") -> 0
A20: 16 | B20: Jourdan-CA | C20: California | D20: PraNikah | E20: =sumifs('KEG. PENGAJIAN HARIAN'!$D$2:$D968,'KEG. PENGAJIAN HARIAN'!$B$2:$B968,">="&$C$2,'KEG. PENGAJIAN HARIAN'!$B$2:$B968,"<="&$E$2,'KEG. PENGAJIAN HARIAN'!$F$2:$F968,B20) -> 0 | F20: 0.5 | G20: =IFERROR(E20/F20,0) -> 0 | H20: =COUNTIFS('KEG. PENGAJIAN HARIAN'!$F$2:$F968,B20,'KEG. PENGAJIAN HARIAN'!$B$2:$B968,">="&$C$2,'KEG. PENGAJIAN HARIAN'!$B$2:$B968,"<="&$E$2,'KEG. PENGAJIAN HARIAN'!$G$2:$G968,"hadir") -> 0 | I20: =COUNTIFS('KEG. PENGAJIAN HARIAN'!$F$2:$F968,B20,'KEG. PENGAJIAN HARIAN'!$B$2:$B968,">="&$C$2,'KEG. PENGAJIAN HARIAN'!$B$2:$B968,"<="&$E$2,'KEG. PENGAJIAN HARIAN'!$G$2:$G968,"By VN") -> 0 | J20: =COUNTIFS('KEG. PENGAJIAN HARIAN'!$F$2:$F968,B20,'KEG. PENGAJIAN HARIAN'!$B$2:$B968,">="&$C$2,'KEG. PENGAJIAN HARIAN'!$B$2:$B968,"<="&$E$2,'KEG. PENGAJIAN HARIAN'!$G$2:$G968,"izin (murid)") -> 0
A21: 17 | B21: Jubilee-CH | C21: Chicago | D21: PraCBR-CBR | E21: =sumifs('KEG. PENGAJIAN HARIAN'!$D$2:$D968,'KEG. PENGAJIAN HARIAN'!$B$2:$B968,">="&$C$2,'KEG. PENGAJIAN HARIAN'!$B$2:$B968,"<="&$E$2,'KEG. PENGAJIAN HARIAN'!$F$2:$F968,B21) -> 0.039583333 | F21: 0.5 | G21: =IFERROR(E21/F21,0) -> 0.079166667 | H21: =COUNTIFS('KEG. PENGAJIAN HARIAN'!$F$2:$F968,B21,'KEG. PENGAJIAN HARIAN'!$B$2:$B968,">="&$C$2,'KEG. PENGAJIAN HARIAN'!$B$2:$B968,"<="&$E$2,'KEG. PENGAJIAN HARIAN'!$G$2:$G968,"hadir") -> 2 | I21: =COUNTIFS('KEG. PENGAJIAN HARIAN'!$F$2:$F968,B21,'KEG. PENGAJIAN HARIAN'!$B$2:$B968,">="&$C$2,'KEG. PENGAJIAN HARIAN'!$B$2:$B968,"<="&$E$2,'KEG. PENGAJIAN HARIAN'!$G$2:$G968,"By VN") -> 0 | J21: =COUNTIFS('KEG. PENGAJIAN HARIAN'!$F$2:$F968,B21,'KEG. PENGAJIAN HARIAN'!$B$2:$B968,">="&$C$2,'KEG. PENGAJIAN HARIAN'!$B$2:$B968,"<="&$E$2,'KEG. PENGAJIAN HARIAN'!$G$2:$G968,"izin (murid)") -> 0
A22: 18 | B22: Kayla-CA | C22: California | D22: PraNikah | E22: =sumifs('KEG. PENGAJIAN HARIAN'!$D$2:$D968,'KEG. PENGAJIAN HARIAN'!$B$2:$B968,">="&$C$2,'KEG. PENGAJIAN HARIAN'!$B$2:$B968,"<="&$E$2,'KEG. PENGAJIAN HARIAN'!$F$2:$F968,B22) -> 0.31041667 | F22: 0.5 | G22: =IFERROR(E22/F22,0) -> 0.62083333 | H22: =COUNTIFS('KEG. PENGAJIAN HARIAN'!$F$2:$F968,B22,'KEG. PENGAJIAN HARIAN'!$B$2:$B968,">="&$C$2,'KEG. PENGAJIAN HARIAN'!$B$2:$B968,"<="&$E$2,'KEG. PENGAJIAN HARIAN'!$G$2:$G968,"hadir") -> 4 | I22: =COUNTIFS('KEG. PENGAJIAN HARIAN'!$F$2:$F968,B22,'KEG. PENGAJIAN HARIAN'!$B$2:$B968,">="&$C$2,'KEG. PENGAJIAN HARIAN'!$B$2:$B968,"<="&$E$2,'KEG. PENGAJIAN HARIAN'!$G$2:$G968,"By VN") -> 0 | J22: =COUNTIFS('KEG. PENGAJIAN HARIAN'!$F$2:$F968,B22,'KEG. PENGAJIAN HARIAN'!$B$2:$B968,">="&$C$2,'KEG. PENGAJIAN HARIAN'!$B$2:$B968,"<="&$E$2,'KEG. PENGAJIAN HARIAN'!$G$2:$G968,"izin (murid)") -> 0
A23: 19 | B23: Khayri-CH | C23: Chicago | D23: PraCBR-CBR | E23: =sumifs('KEG. PENGAJIAN HARIAN'!$D$2:$D968,'KEG. PENGAJIAN HARIAN'!$B$2:$B968,">="&$C$2,'KEG. PENGAJIAN HARIAN'!$B$2:$B968,"<="&$E$2,'KEG. PENGAJIAN HARIAN'!$F$2:$F968,B23) -> 0.34166667 | F23: 0.5 | G23: =IFERROR(E23/F23,0) -> 0.68333333 | H23: =COUNTIFS('KEG. PENGAJIAN HARIAN'!$F$2:$F968,B23,'KEG. PENGAJIAN HARIAN'!$B$2:$B968,">="&$C$2,'KEG. PENGAJIAN HARIAN'!$B$2:$B968,"<="&$E$2,'KEG. PENGAJIAN HARIAN'!$G$2:$G968,"hadir") -> 13 | I23: =COUNTIFS('KEG. PENGAJIAN HARIAN'!$F$2:$F968,B23,'KEG. PENGAJIAN HARIAN'!$B$2:$B968,">="&$C$2,'KEG. PENGAJIAN HARIAN'!$B$2:$B968,"<="&$E$2,'KEG. PENGAJIAN HARIAN'!$G$2:$G968,"By VN") -> 1 | J23: =COUNTIFS('KEG. PENGAJIAN HARIAN'!$F$2:$F968,B23,'KEG. PENGAJIAN HARIAN'!$B$2:$B968,">="&$C$2,'KEG. PENGAJIAN HARIAN'!$B$2:$B968,"<="&$E$2,'KEG. PENGAJIAN HARIAN'!$G$2:$G968,"izin (murid)") -> 2
A24: 20 | B24: Khadijah-RLG | C24: Chicago | D24: PraCBR-CBR | E24: =sumifs('KEG. PENGAJIAN HARIAN'!$D$2:$D968,'KEG. PENGAJIAN HARIAN'!$B$2:$B968,">="&$C$2,'KEG. PENGAJIAN HARIAN'!$B$2:$B968,"<="&$E$2,'KEG. PENGAJIAN HARIAN'!$F$2:$F968,B24) -> 0.57083333 | F24: 0.5 | G24: =IFERROR(E24/F24,0) -> 1.1416667 | H24: =COUNTIFS('KEG. PENGAJIAN HARIAN'!$F$2:$F968,B24,'KEG. PENGAJIAN HARIAN'!$B$2:$B968,">="&$C$2,'KEG. PENGAJIAN HARIAN'!$B$2:$B968,"<="&$E$2,'KEG. PENGAJIAN HARIAN'!$G$2:$G968,"hadir") -> 13 | I24: =COUNTIFS('KEG. PENGAJIAN HARIAN'!$F$2:$F968,B24,'KEG. PENGAJIAN HARIAN'!$B$2:$B968,">="&$C$2,'KEG. PENGAJIAN HARIAN'!$B$2:$B968,"<="&$E$2,'KEG. PENGAJIAN HARIAN'!$G$2:$G968,"By VN") -> 0 | J24: =COUNTIFS('KEG. PENGAJIAN HARIAN'!$F$2:$F968,B24,'KEG. PENGAJIAN HARIAN'!$B$2:$B968,">="&$C$2,'KEG. PENGAJIAN HARIAN'!$B$2:$B968,"<="&$E$2,'KEG. PENGAJIAN HARIAN'!$G$2:$G968,"izin (murid)") -> 1
A25: 21 | B25: Kirana-CH | C25: Chicago | D25: PraCBR-CBR | E25: =sumifs('KEG. PENGAJIAN HARIAN'!$D$2:$D968,'KEG. PENGAJIAN HARIAN'!$B$2:$B968,">="&$C$2,'KEG. PENGAJIAN HARIAN'!$B$2:$B968,"<="&$E$2,'KEG. PENGAJIAN HARIAN'!$F$2:$F968,B25) -> 0.23263889 | F25: 0.5 | G25: =IFERROR(E25/F25,0) -> 0.46527778 | H25: =COUNTIFS('KEG. PENGAJIAN HARIAN'!$F$2:$F968,B25,'KEG. PENGAJIAN HARIAN'!$B$2:$B968,">="&$C$2,'KEG. PENGAJIAN HARIAN'!$B$2:$B968,"<="&$E$2,'KEG. PENGAJIAN HARIAN'!$G$2:$G968,"hadir") -> 11 | I25: =COUNTIFS('KEG. PENGAJIAN HARIAN'!$F$2:$F968,B25,'KEG. PENGAJIAN HARIAN'!$B$2:$B968,">="&$C$2,'KEG. PENGAJIAN HARIAN'!$B$2:$B968,"<="&$E$2,'KEG. PENGAJIAN HARIAN'!$G$2:$G968,"By VN") -> 0 | J25: =COUNTIFS('KEG. PENGAJIAN HARIAN'!$F$2:$F968,B25,'KEG. PENGAJIAN HARIAN'!$B$2:$B968,">="&$C$2,'KEG. PENGAJIAN HARIAN'!$B$2:$B968,"<="&$E$2,'KEG. PENGAJIAN HARIAN'!$G$2:$G968,"izin (murid)") -> 1
A26: 22 | B26: Liv-CH | C26: Chicago | D26: PraCBR-CBR | E26: =sumifs('KEG. PENGAJIAN HARIAN'!$D$2:$D968,'KEG. PENGAJIAN HARIAN'!$B$2:$B968,">="&$C$2,'KEG. PENGAJIAN HARIAN'!$B$2:$B968,"<="&$E$2,'KEG. PENGAJIAN HARIAN'!$F$2:$F968,B26) -> 0.025694444 | F26: 0.5 | G26: =IFERROR(E26/F26,0) -> 0.051388889 | H26: =COUNTIFS('KEG. PENGAJIAN HARIAN'!$F$2:$F968,B26,'KEG. PENGAJIAN HARIAN'!$B$2:$B968,">="&$C$2,'KEG. PENGAJIAN HARIAN'!$B$2:$B968,"<="&$E$2,'KEG. PENGAJIAN HARIAN'!$G$2:$G968,"hadir") -> 1 | I26: =COUNTIFS('KEG. PENGAJIAN HARIAN'!$F$2:$F968,B26,'KEG. PENGAJIAN HARIAN'!$B$2:$B968,">="&$C$2,'KEG. PENGAJIAN HARIAN'!$B$2:$B968,"<="&$E$2,'KEG. PENGAJIAN HARIAN'!$G$2:$G968,"By VN") -> 0 | J26: =COUNTIFS('KEG. PENGAJIAN HARIAN'!$F$2:$F968,B26,'KEG. PENGAJIAN HARIAN'!$B$2:$B968,">="&$C$2,'KEG. PENGAJIAN HARIAN'!$B$2:$B968,"<="&$E$2,'KEG. PENGAJIAN HARIAN'!$G$2:$G968,"izin (murid)") -> 2
A27: 23 | B27: Mikail-CH | C27: Chicago | D27: PraCBR-CBR | E27: =sumifs('KEG. PENGAJIAN HARIAN'!$D$2:$D968,'KEG. PENGAJIAN HARIAN'!$B$2:$B968,">="&$C$2,'KEG. PENGAJIAN HARIAN'!$B$2:$B968,"<="&$E$2,'KEG. PENGAJIAN HARIAN'!$F$2:$F968,B27) -> 0.25138889 | F27: 0.5 | G27: =IFERROR(E27/F27,0) -> 0.50277778 | H27: =COUNTIFS('KEG. PENGAJIAN HARIAN'!$F$2:$F968,B27,'KEG. PENGAJIAN HARIAN'!$B$2:$B968,">="&$C$2,'KEG. PENGAJIAN HARIAN'!$B$2:$B968,"<="&$E$2,'KEG. PENGAJIAN HARIAN'!$G$2:$G968,"hadir") -> 11 | I27: =COUNTIFS('KEG. PENGAJIAN HARIAN'!$F$2:$F968,B27,'KEG. PENGAJIAN HARIAN'!$B$2:$B968,">="&$C$2,'KEG. PENGAJIAN HARIAN'!$B$2:$B968,"<="&$E$2,'KEG. PENGAJIAN HARIAN'!$G$2:$G968,"By VN") -> 0 | J27: =COUNTIFS('KEG. PENGAJIAN HARIAN'!$F$2:$F968,B27,'KEG. PENGAJIAN HARIAN'!$B$2:$B968,">="&$C$2,'KEG. PENGAJIAN HARIAN'!$B$2:$B968,"<="&$E$2,'KEG. PENGAJIAN HARIAN'!$G$2:$G968,"izin (murid)") -> 0
A28: 24 | B28: Nadeen-CH | C28: Chicago | D28: PraCBR-CBR | E28: =sumifs('KEG. PENGAJIAN HARIAN'!$D$2:$D968,'KEG. PENGAJIAN HARIAN'!$B$2:$B968,">="&$C$2,'KEG. PENGAJIAN HARIAN'!$B$2:$B968,"<="&$E$2,'KEG. PENGAJIAN HARIAN'!$F$2:$F968,B28) -> 0.475 | F28: 0.5 | G28: =IFERROR(E28/F28,0) -> 0.95 | H28: =COUNTIFS('KEG. PENGAJIAN HARIAN'!$F$2:$F968,B28,'KEG. PENGAJIAN HARIAN'!$B$2:$B968,">="&$C$2,'KEG. PENGAJIAN HARIAN'!$B$2:$B968,"<="&$E$2,'KEG. PENGAJIAN HARIAN'!$G$2:$G968,"hadir") -> 11 | I28: =COUNTIFS('KEG. PENGAJIAN HARIAN'!$F$2:$F968,B28,'KEG. PENGAJIAN HARIAN'!$B$2:$B968,">="&$C$2,'KEG. PENGAJIAN HARIAN'!$B$2:$B968,"<="&$E$2,'KEG. PENGAJIAN HARIAN'!$G$2:$G968,"By VN") -> 0 | J28: =COUNTIFS('KEG. PENGAJIAN HARIAN'!$F$2:$F968,B28,'KEG. PENGAJIAN HARIAN'!$B$2:$B968,">="&$C$2,'KEG. PENGAJIAN HARIAN'!$B$2:$B968,"<="&$E$2,'KEG. PENGAJIAN HARIAN'!$G$2:$G968,"izin (murid)") -> 0
A29: 25 | B29: Qalesya-ATL | C29: Chicago | D29: PraRMJ-RMJ | E29: =sumifs('KEG. PENGAJIAN HARIAN'!$D$2:$D968,'KEG. PENGAJIAN HARIAN'!$B$2:$B968,">="&$C$2,'KEG. PENGAJIAN HARIAN'!$B$2:$B968,"<="&$E$2,'KEG. PENGAJIAN HARIAN'!$F$2:$F968,B29) -> 0.19305556 | F29: 0.5 | G29: =IFERROR(E29/F29,0) -> 0.38611111 | H29: =COUNTIFS('KEG. PENGAJIAN HARIAN'!$F$2:$F968,B29,'KEG. PENGAJIAN HARIAN'!$B$2:$B968,">="&$C$2,'KEG. PENGAJIAN HARIAN'!$B$2:$B968,"<="&$E$2,'KEG. PENGAJIAN HARIAN'!$G$2:$G968,"hadir") -> 3 | I29: =COUNTIFS('KEG. PENGAJIAN HARIAN'!$F$2:$F968,B29,'KEG. PENGAJIAN HARIAN'!$B$2:$B968,">="&$C$2,'KEG. PENGAJIAN HARIAN'!$B$2:$B968,"<="&$E$2,'KEG. PENGAJIAN HARIAN'!$G$2:$G968,"By VN") -> 0 | J29: =COUNTIFS('KEG. PENGAJIAN HARIAN'!$F$2:$F968,B29,'KEG. PENGAJIAN HARIAN'!$B$2:$B968,">="&$C$2,'KEG. PENGAJIAN HARIAN'!$B$2:$B968,"<="&$E$2,'KEG. PENGAJIAN HARIAN'!$G$2:$G968,"izin (murid)") -> 0
A30: 26 | B30: Rambo-CH | C30: Chicago | D30: PraCBR-CBR | E30: =sumifs('KEG. PENGAJIAN HARIAN'!$D$2:$D968,'KEG. PENGAJIAN HARIAN'!$B$2:$B968,">="&$C$2,'KEG. PENGAJIAN HARIAN'!$B$2:$B968,"<="&$E$2,'KEG. PENGAJIAN HARIAN'!$F$2:$F968,B30) -> 0.46736111 | F30: 0.5 | G30: =IFERROR(E30/F30,0) -> 0.93472222 | H30: =COUNTIFS('KEG. PENGAJIAN HARIAN'!$F$2:$F968,B30,'KEG. PENGAJIAN HARIAN'!$B$2:$B968,">="&$C$2,'KEG. PENGAJIAN HARIAN'!$B$2:$B968,"<="&$E$2,'KEG. PENGAJIAN HARIAN'!$G$2:$G968,"hadir") -> 14 | I30: =COUNTIFS('KEG. PENGAJIAN HARIAN'!$F$2:$F968,B30,'KEG. PENGAJIAN HARIAN'!$B$2:$B968,">="&$C$2,'KEG. PENGAJIAN HARIAN'!$B$2:$B968,"<="&$E$2,'KEG. PENGAJIAN HARIAN'!$G$2:$G968,"By VN") -> 1 | J30: =COUNTIFS('KEG. PENGAJIAN HARIAN'!$F$2:$F968,B30,'KEG. PENGAJIAN HARIAN'!$B$2:$B968,">="&$C$2,'KEG. PENGAJIAN HARIAN'!$B$2:$B968,"<="&$E$2,'KEG. PENGAJIAN HARIAN'!$G$2:$G968,"izin (murid)") -> 2
A31: 27 | B31: Tami-BFL | C31: Chicago | D31: PraNikah | E31: =sumifs('KEG. PENGAJIAN HARIAN'!$D$2:$D968,'KEG. PENGAJIAN HARIAN'!$B$2:$B968,">="&$C$2,'KEG. PENGAJIAN HARIAN'!$B$2:$B968,"<="&$E$2,'KEG. PENGAJIAN HARIAN'!$F$2:$F968,B31) -> 0.24652778 | F31: 0.5 | G31: =IFERROR(E31/F31,0) -> 0.49305556 | H31: =COUNTIFS('KEG. PENGAJIAN HARIAN'!$F$2:$F968,B31,'KEG. PENGAJIAN HARIAN'!$B$2:$B968,">="&$C$2,'KEG. PENGAJIAN HARIAN'!$B$2:$B968,"<="&$E$2,'KEG. PENGAJIAN HARIAN'!$G$2:$G968,"hadir") -> 4 | I31: =COUNTIFS('KEG. PENGAJIAN HARIAN'!$F$2:$F968,B31,'KEG. PENGAJIAN HARIAN'!$B$2:$B968,">="&$C$2,'KEG. PENGAJIAN HARIAN'!$B$2:$B968,"<="&$E$2,'KEG. PENGAJIAN HARIAN'!$G$2:$G968,"By VN") -> 0 | J31: =COUNTIFS('KEG. PENGAJIAN HARIAN'!$F$2:$F968,B31,'KEG. PENGAJIAN HARIAN'!$B$2:$B968,">="&$C$2,'KEG. PENGAJIAN HARIAN'!$B$2:$B968,"<="&$E$2,'KEG. PENGAJIAN HARIAN'!$G$2:$G968,"izin (murid)") -> 1
