Workbook

Sheet KEG. PENGAJIAN HARIAN
A1: Tanggal Isi Form | B1: TANGGAL | C1: BULAN | D1: DURASI | E1: NAMA GURU | F1: NAMA MURID | G1: KEHADIRAN | H1: MATERI: | I1: NO. WHATSAPP | J1: Field_bc728b1
A2: January 3, 2024 2:29 pm | B2: 45294 | C2: {=TEXT((B2:B3480), "mmmm")} -> Januari | D2: 0.0375 | E2: Artha-JG | F2: Nadeen-CH | G2: HADIR | H2: Pembukaan Tepuk2, menyanyi, berdoa Bacaan Tilawaty 4 hal. 31&32 Menulis 4 maqodirulloh PR Menderes tilawaty 4 hal 32 Report Alhamdulillah Nadeen bisa mengikuti pengajian dg sangat baik, bacaan juga meningkat tinggal banyakin nderes dan berlatih mengatur nafas. Semoga Alloh paring Nadeen menjadi anak yg sholihah, alim fakih sukses dunia akhirat. Aamiiin🤲🤲🤲 | I2: 6285606274880
A3: January 8, 2024 2:44 pm | B3: 45299 | C3: Januari | D3: 0.020138889 | E3: Artha-JG | F3: Nadeen-CH | G3: HADIR | H3: Pembukaan Ice breaking Bacaan Tilawaty 4 hal. 32-33 Alhamdulillah bacaan cukup lancar Doa2 Doa berlindung dari syirik Doa masuk pasar Doa menjenguk orang sakit Doa turun hujan Doa ada angin kencang Doa entering toilet Doa tertimpa musibah Doa melihat orang lain tertimpa musibah Menulis angka arab nomer 1-10 Alhamdulillah Nadeen sdh bisa tanpa mencontek, sudah di luar kepala☺ PR Menderes tilawaty 4 hal 33 Menderes doa2 yg pernah di hafal dan me. Praktekannya Report Alhamdulillah Nadeen bisa mengikuti pengajian dg sangat baik dan penuh semangat. Semoga Alloh paring barokah aamiiin🤲 | I3: 6285606274880
A4: January 8, 2024 2:54 pm | B4: 45299 | C4: Januari | D4: 0.044444444 | E4: Artha-JG | F4: Jubilee-CH | G4: HADIR | H4: Pembukaan Tepuk2 Bacaan tilawaty 2 hal. 17 Alhamdulillah bacaannya cukup lancar, boleh melanjutkan ke halaman 18 Doa2 Doa sebelum Dan sesudah makan Doa sebelum Dan sesudah tidur Doa masuk dan keluar kamar mandi Doa untuk kedua orang Tua Doa kebaikan dunia Dan akhirot Doa mencari ilmu Yang bermanfaat Doa minta Ilham Yang baik Doa berpakaian Doa minum susu Doa minta ketetapan iman Doa Mohon kesabaran Doa ketika bersin Bacaan Takbiratul Ikhrom Bacaan ruku' Asmaulhusna 1-20 PR menderes tilawaty 2 hal. 18 Report Alhamdulillah jubilee bisa mengikuti pengajian dg sangat baik 👍 tetap semangat ya Jubilee, sampai ketemu lagi di pertemuan berikutnya👌😘 | I4: 6285606274880
A5: January 10, 2024 3:11 am | B5: 45301 | C5: Januari | D5: 0.05 | E5: Artha-JG | F5: Abi-BFL | G5: HADIR | H5: Bacaan Surat addzariyat ayat 47-60 Murojaah doa2 harian Doa for parent Doa before eating and after eating Doa seeking knowledge 1 & 2 Doa before sleeping and wake up Doa hearing thunder Doa get an accident Doa entering house and leaving house Doa entering toilet and leaving toilet Doa after dreesing Doa iftar Doa seeing another get an accident Doa entering masjid and leaving masjid Doa after adzan Doa before wudhu and after wudhu Asmaulhusna 1-99 Doa ketetapan iman Doa minta ilham yang benar Doa kesabaran versi 1 & 2 Makna surat al an'am ayat 128-130 PR Banyakin nderes bacaan dan doa2 nya Report Alhamdulillah Abi bisa mengikuti pengajian dengan baik😊👍 semoga Alloh paring manfaat dan barokah. Aamiiin 🤲 | I5: 6285606274880
A6: January 10, 2024 1:48 pm | B6: 45301 | C6: Januari | D6: 0.020138889 | E6: Artha-JG | F6: Nadeen-CH | G6: HADIR | H6: Pembukaan Tepuk2 dan doa Bacaan : Tilawaty 4 hal. 33-34 Alhamdulillah bacaan sdh bagus, tetap nderes ya Nadeen Hafalan surat pendek Al alaq Assharh Al qodr Azzalzalah Hafalan surat Nadeen Alhamdulillah lancar sekali👏👍 PR Menderes tilawaty 4 hal 34 Report Alhamdulillah Nadeen bisa mengikuti pengajian dg baik, tidak ada kendala dan anaknya selalu ceria dan semangat. Semoga Alloh paring barokah. Aamiiin🤲 | I6: 6285606274880
A7: January 11, 2024 4:55 am | B7: 45302 | C7: Januari | D7: 0.047916667 | E7: Artha-JG | F7: Abi-BFL | G7: HADIR | H7: Bacaan Surat Atthur ayat 1-28 Tebak2an tajwid Makna surat al an'am ayat 131-133 PR Banyak2 menderes bacaan dan hafalan doanya Report Alhamdulillah bacaan Abi meningkat, tajwidnya juga sdh sesuai dg kaidah baca. Untuk makna dia juga bisa mengikuti dg baik. alhamdulillah tidak ada kendala dlm pengajian. Semoga Alloh paring manfaat dan barokah. Aamiiin🤲 | I7: 6285606274880
A8: January 16, 2024 12:40 pm | B8: 45307 | C8: Januari | D8: 0.030555556 | E8: Artha-JG | F8: Dwiki-RLG | G8: HADIR | H8: Bacaan Surat Al haqqoh ayat 1-19 Makna adilah hal. 68-70 Alhamdulillah Dwiki bisa mengikuti pengajian dg baik. Alhamdulillah sdh mulai pulih shg sdh bisa baca qur'an .semoga lekas sembuh dan tetap semangat ngaji💪 | I8: 6285606274880
A9: January 16, 2024 12:43 pm | B9: 45306 | C9: Januari | D9: 0.020833333 | E9: Artha-JG | F9: Nadeen-CH | G9: HADIR | H9: Bacaan Tilawaty 4 hal. 34-35 Menulis 5 syarat kerukunan Alhamdulillah bacaan Nadeen sdh bagus, tinggal memperbaiki panjang pendeknya, Alhamdulillah jaza killahu hoiro spesial buat bu Gumilar yg selalu dampingi dan support Nadeen. Alhamdulillah jaza kumullohu hoiro buat yanda, bunda dan pak Gumilar juga yg selalu support dan membantu kami untuk kelancaran pengajian 🙏 | I9: 6285606274880
A10: January 17, 2024 2:31 am | B10: 45308 | C10: Januari | D10: 0.052083333 | E10: Artha-JG | F10: Abi-BFL | G10: HADIR | H10: Bacaan Surat atthur ayat 29-49 Murojaah doa2 dan surat pendek: Doa for parent✅ Doa before eating and after eating✅ Doa seeking knowledge 1 & 2❎ Doa before sleeping and wake up✅ Doa hearing thunder❎ Doa get an accident❎ Doa entering house❎ and leaving house✅ Doa entering toilet and leaving toilet✅ Doa after dreesing❎ Doa iftar✅ Doa seeing another get an accident❎ Doa entering masjid and leaving masjid❎ Doa after adzan❎ Doa before wudhu and after wudhu✅ Asmaulhusna 1-99 ❎ Surat2 pendek Annas✅ Al falaq✅ Al ikhlas✅ Al lahab✅ Annashr✅ Al-kafirun (ada mbulet di ayat 4😅) Al kautsar✅ Ala'un✅ Attakatsur✅ Al fiil✅ Al humazah✅ Annashr✅ Makna surat al an'am ayat 134-136 Report: Alhamdulillah bacaan Abi semakin meningkat tapi untuk doa2 banyak yg lupa/belum hafal jadi saya kasih PR nge print doa2 yg sdh saya kirim, setiap sebelum tidur nderes asmaulhusna dan setiap habis subuh nderes bacaan minimal 3 ayat dan murojaah semua doa2 Mohon amal sholih pak Syahrul untuk mengingatkan Abi PR nya. Mudah2an alloh paring barokah. Tetap semangat ya Bi 💪 | I10: 6285606274880
A11: January 17, 2024 2:00 pm | B11: 45308 | C11: Januari | D11: 0.022916667 | E11: Artha-JG | F11: Dwiki-RLG | G11: HADIR | H11: Bacaan Surat al haqqoh ayat 20-52 Makna Surat al an'am ayat 130-133 Alhamdulillah Dwiki bisa mengikuti pengajian dengan baik. Alhamdulillah jaza kallohu hoiro Dwiki sdh melonggarkan waktunya. Jgn lupa banyak nderes. | I11: 6285606274880
A12: January 18, 2024 1:45 pm | B12: 45309 | C12: Januari | D12: 0.023611111 | E12: Artha-JG | F12: Jubilee-CH | G12: HADIR | H12: Bacaan Tilawaty 4 hal 37 Menceritakan ttg nabi adam dan hawa Menceritakan 10 nama malaikat PR. Nderes tilawaty 4 hal. 37 Mempraktikkan doa2 yg sdh di hafal dlm kehidupan sehari-hari Mencatat doa minta kesehatan(saya kirim menyusul) Report Alhamdulillah pengajian bisa berjalan dg lancar tanpa kendala. Nadeen nya juga selalu punya aura positif ketika mengaji, selalu ceria dan semangat👍semoga Alloh paring manfaat dan barokah. Aamiiin🤲 | I12: 6285606274880
A13: January 22, 2024 1:38 pm | B13: 45313 | C13: Januari | D13: 0.022222222 | E13: Artha-JG | F13: Nadeen-CH | G13: HADIR | H13: 𝘉𝘢𝘤𝘢𝘢𝘯 𝘛𝘪𝘭𝘢𝘸𝘢𝘵𝘺 4 𝘩𝘢𝘭. 37-38 𝘏𝘢𝘧𝘢𝘭𝘢𝘯 𝘴𝘶𝘳𝘢𝘵 𝘱𝘦𝘯𝘥𝘦𝘬 -𝘈𝘥𝘥𝘻𝘶𝘩𝘢 -𝘢𝘭 𝘢𝘭𝘢𝘲 -𝘢𝘭 𝘮𝘢𝘶𝘯 -𝘢𝘭 𝘲𝘶𝘳𝘢𝘪𝘴𝘺 -𝘢𝘭 𝘧𝘪𝘭𝘭 -𝘢𝘭 𝘩𝘶𝘮𝘢𝘻𝘢𝘩 -𝘢𝘭 𝘢𝘴𝘩𝘳 -𝘢𝘵𝘵𝘢𝘬𝘢𝘵𝘴𝘶𝘳 -𝘢𝘭 𝘲𝘰𝘳𝘪'𝘢𝘩 𝘗𝘙 𝘔𝘦𝘯𝘥𝘦𝘳𝘦𝘴 𝘵𝘪𝘭𝘢𝘸𝘢𝘵𝘺 4 𝘩𝘢𝘭. 38 𝘙𝘦𝘱𝘰𝘳𝘵 𝘈𝘭𝘩𝘢𝘮𝘥𝘶𝘭𝘪𝘭𝘭𝘢𝘩 𝘣𝘢𝘤𝘢𝘢𝘯 𝘕𝘢𝘥𝘦𝘦𝘯 𝘣𝘢𝘨𝘶𝘴, 𝘴𝘦𝘮𝘢𝘬𝘪𝘯 𝘮𝘦𝘯𝘪𝘯𝘨𝘬𝘢𝘵, 𝘩𝘢𝘧𝘢𝘭𝘢𝘯𝘯𝘺𝘢 𝘫𝘶𝘨𝘢 𝘣𝘢𝘨𝘶𝘴. 𝘚𝘦𝘮𝘰𝘨𝘢 𝘈𝘭𝘭𝘰𝘩 𝘱𝘢𝘳𝘪𝘯𝘨 𝘮𝘢𝘯𝘧𝘢𝘢𝘵 𝘥𝘢𝘯 𝘣𝘢𝘳𝘰𝘬𝘢𝘩. 𝘈𝘢𝘮𝘪𝘪𝘪𝘯🤲 | I13: 6285606274880
A14: January 23, 2024 2:34 pm | B14: 45314 | C14: Januari | D14: 0.015277778 | E14: Artha-JG | F14: Jubilee-CH | G14: HADIR | H14: 𝘉𝘢𝘤𝘢𝘢𝘯 𝘛𝘪𝘭𝘢𝘸𝘢𝘵𝘺 4 𝘩𝘢𝘭. 26 𝘉𝘢𝘤𝘢𝘢𝘯𝘯𝘺𝘢 𝘮𝘢𝘴𝘪𝘩 𝘬𝘶𝘳𝘢𝘯𝘨 𝘵𝘦𝘭𝘪𝘵𝘪 𝘩𝘢𝘳𝘰𝘬𝘢𝘵𝘯𝘺𝘢 𝘴𝘶𝘬𝘢 𝘬𝘦𝘵𝘶𝘬𝘦𝘳 𝘩𝘢𝘳𝘰𝘬𝘢𝘵𝘯𝘺𝘢. 𝘔𝘪𝘴𝘢𝘭𝘯𝘺𝘢 𝘵𝘶𝘯 𝘥𝘪 𝘣𝘢𝘤𝘢 𝘵𝘪𝘯 𝘗𝘙 𝘯𝘥𝘦𝘳𝘦𝘴 𝘭𝘢𝘨𝘪 𝘵𝘪𝘭𝘢𝘸𝘢𝘵𝘺 4 𝘩𝘢𝘭 26 𝘔𝘰𝘩𝘰𝘯 𝘮𝘢𝘢𝘧 𝘬𝘢𝘳𝘯𝘢 𝘸𝘢𝘬𝘵𝘶𝘯𝘺𝘢 𝘤𝘶𝘮𝘢 𝘴𝘦𝘣𝘦𝘯𝘵𝘢𝘳 𝘯𝘨𝘢𝘫𝘪𝘯𝘺𝘢 𝘤𝘶𝘮𝘢 𝘣𝘪𝘴𝘢 𝘵𝘪𝘭𝘢𝘸𝘢𝘵𝘺 𝘴𝘢𝘫𝘢. 𝘛𝘪𝘥𝘢𝘬 𝘢𝘱𝘢2 𝘺𝘢 𝘫𝘶𝘣𝘪𝘭𝘦𝘦 ,𝘮𝘢𝘴𝘪𝘩 𝘮𝘢𝘴𝘢 𝘱𝘦𝘯𝘺𝘦𝘴𝘶𝘢𝘪𝘢𝘯 .𝘪𝘯𝘴𝘺𝘢𝘢𝘭𝘭𝘢𝘩 𝘴𝘢𝘺𝘢 𝘥𝘢𝘯 𝘮𝘣𝘬 𝘦𝘳𝘮𝘢 𝘢𝘬𝘢𝘯 𝘮𝘶𝘴𝘺𝘢𝘸𝘢𝘳𝘢𝘩 𝘭𝘢𝘨𝘪 𝘵𝘵𝘨 𝘱𝘦𝘮𝘣𝘢𝘨𝘪𝘢𝘯 𝘩𝘢𝘳𝘪 𝘮𝘦𝘯𝘨𝘢𝘫𝘢𝘳 𝘣𝘶𝘢𝘵 𝘫𝘶𝘣𝘪𝘭𝘦𝘦. 𝘛𝘦𝘵𝘢𝘱 𝘴𝘦𝘮𝘢𝘯𝘨𝘢𝘵 𝘺𝘢 𝘴𝘢𝘺𝘢𝘯𝘨💕 💪𝘮𝘶𝘥𝘢𝘩2𝘢𝘯 𝘈𝘭𝘭𝘰𝘩 𝘱𝘢𝘳𝘪𝘯𝘨 𝘮𝘢𝘯𝘧𝘢𝘢𝘵 𝘥𝘢𝘯 𝘣𝘢𝘳𝘰𝘬𝘢𝘩 | I14: 6285606274880
... A72: March 14, 2024 1:40 am | B72: 45365 | C72: Maret | D72: 0.022916667 | E72: Artha-JG | F72: Abi-BFL | G72: HADIR | H72: Bacaan Surat Alhadid ayat 28-29 Makna surat Al Baqarah ayat 36-39 Report Alhamdulillah Abi bisa mengikuti pengajian dg baik. Semoga Alloh paring manfaat dan barokah. Aamiiin aamiiin aamiiin 🤲🙏 | I72: 6285606274880
C73: Desember
A74: March 16, 2024 12:20 pm | B74: 45367 | C74: Maret | D74: 0.022916667 | E74: Artha-JG | F74: Jubilee-CH | G74: HADIR | H74: Bacaan Tilawaty 2 page 42&43 Tepuk 5 bab Tepuk 4 tali keimanan Doa hearing thunder ⚡ Doa get an accident (she follows after me) Home work Menderes tilawaty 2 page 44 Menderes and memorize doa get an accident Report Alhamdulillah Jubilee can follow the ngaji well. Cheerfully, She also can recites the tilawaty fluently. She can go to the next page. Yey 👏 it's the last part of tilawaty 2.may Alloh give benefits and barokah. See you on the next ngaji Jubilee 🤏 الحمدلله جزاكم الله خيرا | I74: 6285606274880
A75: March 18, 2024 1:08 am | B75: 45369 | C75: Maret | D75: 0.025 | E75: Artha-JG | F75: Jubilee-CH | G75: HADIR | H75: Bacaan Tilawaty 2 hal. 44 Tepuk 5 bab Tepuk 4 tali keimanan Doa seeking knowledge 1 Doa minta kemudahan Doa get an accident Doa hearing thunder Doa rukuk Doa i'tidal Asmaulhusna 1-40 Murojaah surat Al lahab PR Menderes tilawaty 3 hal 1 Report Alhamdulillah Jubilee semangat mengaji, she can follows the ngaji well. But she said she sleepy. so, we finished the ngaji . Ok. Good job jubilee. May Alloh give benefits and barokah. Aamiiin 🤲🤲🤲 | I75: 6285606274880
A76: March 20, 2024 2:06 am | B76: 45371 | C76: Maret | D76: 0.029861111 | E76: Artha-JG | F76: Abi-BFL | G76: HADIR | H76: Bacaan surat al mujadalah ayat 1-3 Makna surat al baqoroh ayat 40-41 Report Alhamdulillah Abi bisa mengikuti pengajian dg baik , amal sholih banyak nderes supaya bacaannya semakin tambah Lancar. Semoga Alloh paring manfaat dan barokah. Aamiiin | I76: 6285606274880
A77: March 21, 2024 1:48 am | B77: 45372 | C77: Maret | D77: 0.029861111 | E77: Artha-JG | F77: Abi-BFL | G77: HADIR | H77: Bacaan Surat Al mujadalah ayat 4-6 Makna surat al baqoroh ayat 42-48 Alhamdulillah Abi bisa mengikuti pengajian dg baik👍. Semoga Alloh paring manfaat dan barokah. Aamiiin🤲 | I77: 6285606274880
A78: March 23, 2024 12:46 am | B78: 45374 | C78: Maret | D78: 0.022916667 | E78: Artha-JG | F78: Jubilee-CH | G78: HADIR | H78: Bacaan Tilawaty 3 page 1 Doa2 Doa get an accident Doa hearing thunder⚡ Doa minta ilham yg benar Doa for parent Doa drinking milk Doa before and after eating Doa before sleeping and wake up Doa after dressing Asmaulhusna 1-40 Report Alhamdulillah Jubilee can follows the ngaji well, although she was not at her home but she can focus and semangat during ngaji. Good job jubilee 😙👍👏🤏🙏 Her bacaan is good enough, she can go to the next page. Don't forget to nderes ya jubilee. May Alloh give benefits and barokah. Aamiiin🤲 She can go to the next page | I78: 6285606274880
A79: March 27, 2024 2:41 am | B79: 45378 | C79: Maret | D79: 0.029861111 | E79: Artha-JG | F79: Abi-BFL | G79: HADIR | H79: Bacaan Surat Al mujadalah ayat 7-8 Makna surat Al baqoroh ayat 49-54 Report Alhamdulillah pengajian bisa berjalan dg lancar, Abi juga bisa mengikuti dg baik👍 Semoga Alloh paring manfaat dan barokah. Aamiiin🤲 🙏 | I79: 6285606274880
A80: March 28, 2024 1:55 am | B80: 45379 | C80: Maret | D80: 0.00069444444 | E80: Artha-JG | F80: Abi-BFL | G80: HADIR | H80: Bacaan Surat al mujadalah ayat 9-11 Makna surat Al-Baqarah ayat 55-57 Report Alhamdulillah Abi bisa mengikuti pengajisn dg baik, amal sholih di tingkatkan nderesnya spy bacaannya semakin lancar. Semoga Alloh paring manfaat dan barokah. Aamiiin🤲 | I80: 6285606274880
A81: January 10, 2024 6:37 am | B81: 45300 | C81: Januari | D81: 0.0625 | E81: Ayu-CKP | F81: Kayla-CA | G81: HADIR | H81: � Bacaan : Al-Qur'an Surat Ar-Rdu ayat 41-45 & Al-Mulk ayat 1-selesai � Mencari Tajwid yg sudah diajarkan di surat yang dibaca � Doa2 Pembuka & Murojaah Target Hafalan - Doa Pagi dan Sore yang panjang - Raja Istighfar - Mencari Ilmu 1 & 2 - Doa Minta Ilham Yang Baik - Doa ketetapan Iman - Asmaul Husnah - PR 13 - Doa Asad - Ayat Kursi - Surat Al-kahfi - Surat Al-Mulk - Doa Kedua orang tua - Doa Kebaikan Dunia dan Akhirat - Doa Bangun Dari Duduk - Doa Minta Kesabaran 1&2 - Doa Berlindung dari 4 Hal � Review Dalil 5 BAB & 4 Tali Keimanan � PR: - Menderes Al-Qur'an Surat Ar-Rdu Ayat 31-35 - Menghafal Tajwid Idhar Halqi & Idghom Bigunnah - Mempraktekan pelajaran atau materi yang sudah diajarkan di kehidupan sehari-hari � Report Alhamdulillah Teh Kayla bisa mengikuti pengajian dg baik, Mudah - mudahan Alloh paring manfaat barokah. Aamiiin... ����������� | I81: 62895632016027
A82: January 25, 2024 6:18 am | B82: 45307 | C82: Januari | D82: 0.084027778 | E82: Ayu-CKP | F82: Kayla-CA | G82: HADIR | H82: � Bacaan : Al-Qur'an Surat Ar-Rdu ayat 31-35 & Al-Mulk ayat 1-selesai � Mencari Tajwid yg sudah diajarkan di surat yang dibaca � Doa2 Pembuka & Murojaah Target Hafalan - Doa Pagi dan Sore yang panjang - Raja Istighfar - Mencari Ilmu 1 & 2 - Doa Minta Ilham Yang Baik - Doa ketetapan Iman - Asmaul Husnah - PR 13 - Doa Asad - Ayat Kursi - Surat Al-kahfi - Surat Al-Mulk - Doa Kedua orang tua - Doa Kebaikan Dunia dan Akhirat - Doa Bangun Dari Duduk - Doa Minta Kesabaran 1&2 - Doa Berlindung dari 4 Hal � Review Dalil 5 BAB & 4 Tali Keimanan � PR: - Menderes Al-Qur'an Surat Ar-Rdu Ayat 31-35 - Menghafal Tajwid Idhar Halqi & Idghom Bigunnah - Mempraktekan pelajaran atau materi yang sudah diajarkan di kehidupan sehari-hari � Report Alhamdulillah Teh Kayla bisa mengikuti pengajian dg baik, Mudah - mudahan Alloh paring manfaat barokah. Aamiiin... ����������� | I82: 62895632016027
A83: January 25, 2024 6:21 am | B83: 45314 | C83: Januari | D83: 0.076388889 | E83: Ayu-CKP | F83: Kayla-CA | G83: HADIR | H83: � Bacaan : Al-Qur'an Surat Ar-Rdu ayat 36-38 & Al-Mulk ayat 1-selesai � Mencari Tajwid yg sudah diajarkan di surat yang dibaca � Doa2 Pembuka & Murojaah Target Hafalan - Doa Pagi dan Sore yang panjang - Raja Istighfar - Mencari Ilmu 1 & 2 - Doa Minta Ilham Yang Baik - Doa ketetapan Iman - Asmaul Husnah - PR 13 - Doa Asad - Ayat Kursi - Surat Al-kahfi - Surat Al-Mulk - Doa Kedua orang tua - Doa Kebaikan Dunia dan Akhirat - Doa Bangun Dari Duduk - Doa Minta Kesabaran 1&2 - Doa Berlindung dari 4 Hal � Review Dalil 5 BAB & 4 Tali Keimanan � PR: - Menderes Al-Qur'an Surat Ar-Rdu Ayat 31-35 - Menghafal Tajwid Idhar Halqi & Idghom Bigunnah - Mempraktekan pelajaran atau materi yang sudah diajarkan di kehidupan sehari-hari � Report Alhamdulillah Teh Kayla bisa mengikuti pengajian dg baik, Mudah - mudahan Alloh paring manfaat barokah. Aamiiin... ����������� | I83: 62895632016027
A84: January 31, 2024 11:17 am | B84: 45321 | C84: Januari | D84: 0.078472222 | E84: Ayu-CKP | F84: Kayla-CA | G84: HADIR | H84: � Bacaan : Al-Qur'an Surat Ibrahim ayat 1-5 & Al-Mulk ayat 1-selesai � Mencari Tajwid yg sudah diajarkan di surat yang dibaca � Doa2 Pembuka & Murojaah Target Hafalan - Doa Pagi dan Sore yang panjang - Raja Istighfar - Mencari Ilmu 1 & 2 - Doa Minta Ilham Yang Baik - Doa ketetapan Iman - Asmaul Husnah - PR 13 - Doa Asad - Ayat Kursi - Surat Al-kahfi - Surat Al-Mulk - Doa Kedua orang tua - Doa Kebaikan Dunia dan Akhirat - Doa Bangun Dari Duduk - Doa Minta Kesabaran 1&2 - Doa Berlindung dari 4 Hal � Review Dalil 5 BAB & 4 Tali Keimanan 5️⃣ Nasehat pemahaman 5 Alam kehidupan manusia � PR: - Menderes Al-Qur'an Surat Ar-Rdu Ayat 31-35 - Menghafal Tajwid Idhar Halqi & Idghom Bigunnah - Mempraktekan pelajaran atau materi yang sudah diajarkan di kehidupan sehari-hari � Report Alhamdulillah Teh Kayla bisa mengikuti pengajian dg baik, Mudah - mudahan Alloh paring manfaat barokah. Aamiiin... ����������� | I84: 62895632016027
A85: February 6, 2024 2:31 pm | B85: 45328 | C85: Februari | D85: 0.00069444444 | E85: Ayu-CKP | F85: Kayla-CA | G85: IZIN (MURID) | H85: Ada ujian | I85: 62895632016027
... A90: March 8, 2024 2:22 pm | B90: 45359 | C90: Maret | D90: 0.00069444444 | E90: Ayu-CKP | F90: Khayri-CH | G90: HADIR | H90: 1. Bacaan Tilawaty hal 1-3 85% Alkhamdulillah Khay bisa mengikuti dan memperhatikan dengan baik, lancar bacaanya dan semangat banget MasayaAllah, tinggal menghafal lagi huruf hijayah ث 2. Hafalan Surat Alfatihah 70% tinggal ayat terakhir saja belum hafal dan lancar 3. Doa mau tidur dan wake up 97% lancar hanya saja masih tergesa2 membacanya 🌼🫶🏻🤗 *Tugas dirumah, yeeeeeee* 🥳 1. Menderes Tilawaty Hal 3 2. Mengamalkan doa2 sehari2 Semoga Khay menjadi anak yg sholih, Berakhlaqul Karimah, Alim Faqih dan Mandiri barokah, serta semoga Alloh paring kelancaran kebarokahan dan kemudahan serta dipermudah dalam belajarnya📚 dan mempraktekan nya, Aamiin Sampai berjumpa lagi Mass Khay 👋🏻🫶🏻😊🌸💞 | I90: 62895632016027
A91: March 9, 2024 4:31 am | B91: 45360 | C91: Maret | D91: 0.065972222 | E91: Ayu-CKP | F91: Kayla-CA | G91: HADIR | H91: ===================== *LAPORAN PENGAJIAN PPG* ===================== ● *Murid:* Kayla-CA ● *Tanggal:* 2024-02-29 ● *Guru:* Ayu-CKP ● *Durasi:* 01:45 ● *Materi:* 1. Bacaan Al-Quran surat Ibrohim Ayat 6-10 (mencari tajwid) 2. Murojaah surat Al-Mulk 1-selesai 3. Murojaah / Membaca - Doa pagi sore versi lengkap - Doa Asad - Asmaul Khusna - PR 13 - Ayat Kursi - Doa Mencari Imu 1&2 - Doa Minta Ilham yang baik - Surat Alkahfi 1-10 - Surat Al-Baqoroh 1-5 Alhamdulillah kayla dapat mengikuti pengajian dengan sangat baik dan semangat Moga2 Allah Paring Ilmu Manfaat dan Barokah الحمدلله جزاكم الله خيرا ===================== *LAPORAN PENGAJIAN PPG* ===================== ● *Murid:* Kayla-CA ● *Tanggal:* 2024-02-22 ● *Guru:* Ayu-CKP ● *Durasi:* 01:05 ● *Materi:* 1. Bacaan Al-Quran surat Ibrohim Ayat 11-15 (mencari tajwid) 2. Murojaah surat Al-Mulk 1-selesai 3. Murojaah / Membaca - Doa pagi sore versi lengkap - Doa Asad - Asmaul Khusna - PR 13 - Ayat Kursi - Doa Mencari Imu 1&2 - Doa Minta Ilham yang baik - Surat Alkahfi 1-10 - Surat Al-Baqoroh 1-5 Alhamdulillah kayla dapat mengikuti pengajian dengan sangat baik dan semangat Moga2 Allah Paring Ilmu Manfaat dan Barokah -> #ERROR! | I91: 62895632016027
A92: March 14, 2024 2:42 am | B92: 45365 | C92: Maret | D92: 0.00069444444 | E92: Ayu-CKP | F92: Kayla-CA | G92: IZIN (MURID) | H92: Izin 2 minggu sedang ujian | I92: 62895632016027
A93: January 4, 2024 2:44 am | B93: 45295 | C93: Januari | D93: 0.0625 | E93: Azki-MDN | F93: Tami-BFL | G93: HADIR | H93: 1. Bacaan quran surat al qosos 29-35 2. Makna k.nawafil 78-79 3. Rukun Islam = alhamdulillah tami bisa mengikuti pengajian dengan sangat baik Moga2 Allah paring ilmu manfaat dan barokah...amin | I93: 6285313543592
A94: January 5, 2024 4:41 pm | B94: 45295 | C94: Januari | D94: 0.058333333 | E94: Azki-MDN | F94: Kayla-CA | G94: HADIR | H94: 1. Murojaah surat al mulk 2. Makna hadits jannah wannar hal. 3-5 Alhamdulillah kayla mengikuti pengajian dengan sangat baik Moga2 Allah paring ilmu manfaat dan barokah | I94: 6285313543592
A95: January 8, 2024 2:12 am | B95: 45299 | C95: Januari | D95: 0.069444444 | E95: Azki-MDN | F95: Denissa-RLG | G95: HADIR | H95: 1. Menulis doa kumpulan nabi 2. Murojaah doa pengayoman, doa masuk pasar, doa ketika ada angin kencang, doa minta kesehatan dan tebak2an doa 3. Makna bahasa indonesia k.jannah wannar hal. 21-22 Alhamdulillah nissa masih bisa mengikuti pengajian dengan sangat baik meskipun sakit batuk2... Moga2 Allah paring nissa segera sembuh sehat barokah...amin | I95: 6285313543592
A96: January 10, 2024 6:21 am | B96: 45301 | C96: Januari | D96: 0.040277778 | E96: Azki-MDN | F96: Kayla-CA | G96: HADIR | H96: K. Jannah Wannar hal. 6-7 Alhamdulillah kayla bisa mengikuti pengajian dengan baik | I96: 6285313543592
A97: January 11, 2024 2:33 am | B97: 45302 | C97: Januari | D97: 0.063888889 | E97: Azki-MDN | F97: Tami-BFL | G97: HADIR | H97: 1. Doa sujud al quran = alhamdulillah sudah ditulis dan dibaca berulang kali, tinggal dihapalin 2. Membaca Al quran surat Al-Qosos 44-46 =alhamdulillah bacanya pelan2 bagus, tinggal banyak latihan atur nafas dan membaca ulang di kata yang tepat 3. Makna hadits k.nawafil hal. 80-81 = alhamdulillah dapat mengikuti makna dgn sangat baik dan dapat menjelaskan ulang beberapa hadits | I97: 6285313543592
A98: January 12, 2024 3:22 am | B98: 45303 | C98: Januari | D98: 0.047222222 | E98: Azki-MDN | F98: Chester-PD | G98: HADIR | H98: 1. Membaca tilawati 4 hal. 17 = alhamdulillah sudah cukup baik bacaannya tinggal di perhatikan lagi bacaan2 yg panjang di akhir ayat (mad aridh lisskunnya) Tapi boleh naik ke hal. Berikutnya 2. Menulis doa pagi sore = amsol dihafalkan 3. Hafalan surat an nasr = alhamdulillah sudah hafal semua 4. Hafalan asmaul husna 1-40 = 31-40 masih perlu diulang2 lagi hafalnnya Moga2 Allah paring ilmu manfaat dan barokah..amin | I98: 6285313543592
A99: January 16, 2024 1:50 pm | B99: 45306 | C99: Januari | D99: 0.048611111 | E99: Azki-MDN | F99: Chester-PD | G99: HADIR | H99: 1. Tilawati 4 hal. 18 = amal solih di ulang lagi yaa, supaya lebih lancar 2. Menulis "The etiquette of respect to the elder and love to the younger" = Alhamdulillah sudah di tulis chester, insyaallah akan di jelaskan di pertemuan berikutnya 3. Hafalan doa pagi dan sore Moga2 Allah paring ilmu manfaat dan barokah.. Aaamiin | I99: 6285313543592
A100: January 19, 2024 7:12 am | B100: 45308 | C100: Januari | D100: 0.0625 | E100: Azki-MDN | F100: Kayla-CA | G100: HADIR | H100: 1. Makn dan Keterangan K. Jannah Wannar hal. -9 2. Murajaah surat Al-Mulk Alhamdulillah kayla dapat mengikuti pengajian dengan sangat baik Moga2 Allah paring ilmu manfaat dan barokah,, Amin | I100: 6285313543592
A101: January 24, 2024 8:07 am | B101: 45315 | C101: Januari | D101: 0.061111111 | E101: Azki-MDN | F101: Kayla-CA | G101: HADIR | H101: 1. Makna dan keterangan k. Jannah wannar hal. 9-12 2. Tes doa2 Alhamdulillah kayla dapat mengikuti pengajian dengan sangat baik. Moga2 Allah paring ilmu manfaat dan barokah... aamiin | I101: 6285313543592
...

Sheet Durasi ngajar guru
A1: SUM of DURASI | B1: NAMA GURU
A2: NAMA MURID | B2: Ammar-JG | C2: Artha-JG | D2: Ayu-CKP | E2: Azki-MDN | F2: Bella-PWD | G2: Dilla-MLL | H2: Erma-BKS | I2: Fadly-SMG | J2: Fauzan-SL3 | K2: Ilham-Solo | L2: Millati-PWD | M2: Mora-MLL | N2: Naely-BGR | O2: Nedha-PWD | P2: Rika-KDR | Q2: Wulan-PWD | R2: Zul-Mll | S2: Grand Total
A3: Abell-NH | D3: 0.55 | L3: 0.76805556 | N3: 0.125 | O3: 0.24166667 | S3: 1.6847222
A4: Abi-BFL | C4: 3.4861111 | O4: 0.036805556 | Q4: 0.048611111 | R4: 0.31875 | S4: 3.8902778
A5: Cheryl-NH | D5: 0.042361111 | L5: 0.15972222 | N5: 0.29861111 | O5: 0.85555556 | S5: 1.35625
A6: Chester-PD | E6: 1.61875 | G6: 0.21041667 | M6: 1.03125 | Q6: 2.0083333 | S6: 4.86875
A7: Dawud-RLG | B7: 0.98263889 | H7: 0.054861111 | M7: 0.81111111 | O7: 0.045138889 | Q7: 1.6451389 | S7: 3.5388889
A8: Dehan-CND | I8: 0.05625 | L8: 0.50069444 | M8: 2.3180556 | Q8: 0.50833333 | S8: 3.3833333
A9: Denissa-RLG | E9: 0.71180556 | M9: 0.50763889 | Q9: 0.042361111 | S9: 1.2618056
A10: Dihyah-PWD | F10: 0.00069444444 | S10: 0.00069444444
A11: Dinda-RLG | G11: 1.3680556 | H11: 0.32847222 | L11: 0.5 | S11: 2.1965278
A12: Dwiki-RLG | C12: 1.3777778 | G12: 0.036805556 | O12: 0.030555556 | R12: 0.041666667 | S12: 1.4868056
A13: Dylan-CA | G13: 0.93680556 | K13: 1.1541667 | M13: 0.049305556 | O13: 0.12361111 | Q13: 0.075 | S13: 2.3388889
A14: Fitri-CND | G14: 1.6180556 | O14: 0.13958333 | P14: 0.84027778 | S14: 2.5979167
A15: Gabriel-CH | I15: 1.1493056 | J15: 1.9298611 | K15: 0.045138889 | S15: 3.1243056
A16: Grazia-IN | G16: 2.4958333 | H16: 0.14375 | J16: 0.024305556 | L16: 1.0826389 | N16: 1.9402778 | Q16: 0.077777778 | S16: 5.7645833
A17: Hafiz-PTM | E17: 0.79027778 | O17: 0.77847222 | Q17: 0.041666667 | S17: 1.6104167
A18: Irsan-CH | C18: 2.5347222 | G18: 0.09375 | O18: 0.039583333 | P18: 0.28888889 | R18: 0.49236111 | S18: 3.4493056
A19: Jourdan-CA | K19: 0.42708333 | S19: 0.42708333
A20: Jubilee-CH | C20: 1.2069444 | G20: 0.21180556 | H20: 0.029166667 | M20: 1.1076389 | Q20: 1.3888889 | S20: 3.9444444
A21: Kayla-CA | D21: 1.7569444 | E21: 0.59791667 | G21: 0.011805556 | H21: 1.0222222 | S21: 3.3888889
A22: Khayri-CH | D22: 0.00069444444 | F22: 2.3659722 | G22: 0.29791667 | N22: 0.024305556 | P22: 0.62569444 | S22: 3.3145833
A23: Khodija-RLG | D23: 0.3875 | M23: 1.2763889 | O23: 0.67430556 | S23: 2.3381944
A24: Kirana-CH | J24: 1.0888889 | N24: 1.9097222 | Q24: 0.052083333 | S24: 3.0506944
A25: Liv-CH | G25: 0.10208333 | P25: 0.62916667 | S25: 0.73125
A26: Mikail-CH | G26: 0.017361111 | I26: 1.9555556 | N26: 1.0611111 | Q26: 0.027777778 | S26: 3.0618056
A27: Nadeen-CH | C27: 0.40416667 | E27: 0.27222222 | G27: 1.1833333 | P27: 1.5173611 | S27: 3.3770833
A28: Qalesya-ATL | H28: 1.3388889 | S28: 1.3388889
A29: Rambo-CH | C29: 0.038194444 | D29: 0.097222222 | F29: 2.4027778 | G29: 0.15208333 | P29: 1.1125 | S29: 3.8027778
A30: Tami-BFL | E30: 1.8958333 | G30: 0.58680556 | K30: 2.0076389 | L30: 0.049305556 | M30: 0.14097222 | O30: 0.095833333 | Q30: 0.085416667 | R30: 0.053472222 | S30: 4.9152778
A31: Zahra-RLG | M31: 0.71388889 | Q31: 0.72013889 | S31: 1.4340278
A32: Grand Total | B32: 0.98263889 | C32: 9.0479167 | D32: 2.8347222 | E32: 5.8868056 | F32: 4.7694444 | G32: 9.3229167 | H32: 2.9173611 | I32: 3.1611111 | J32: 3.0430556 | K32: 3.6340278 | L32: 3.0604167 | M32: 7.95625 | N32: 5.3590278 | O32: 3.0611111 | P32: 5.0138889 | Q32: 6.7215278 | R32: 0.90625 | S32: 77.678472
A34: Urutan Durasi Terbanyak
A35: Dilla-MLL | B35: 9.3229167
A36: Artha-JG | B36: 9.0479167
A37: Mora-MLL | B37: 7.95625
A38: Wulan-PWD | B38: 6.7215278
A39: Azki-MDN | B39: 5.8868056
A40: Naely-BGR | B40: 5.3590278
A41: Rika-KDR | B41: 5.0138889
...

Sheet Januari
A1: REKAPITULASI KEHADIRAN GURU MENGAJAR - PENGAJIAN PPG US
B2: Mulai : | E2: 45292 | F2: Hingga : | G2: 45322
A4: NO. | B4: NAMA GURU | E4: DURASI MENGAJI | F4: TARGET DURASI | G4: % DURASI | H4: JUMLAH PERTEMUAN
A5: 1 | B5: Artha-JG | E5: =sumifs('KEG. PENGAJIAN HARIAN'!$D$2:$D979,'KEG. PENGAJIAN HARIAN'!$B$2:$B979,">="&$E$2,'KEG. PENGAJIAN HARIAN'!$B$2:$B979,"<="&$G$2,'KEG. PENGAJIAN HARIAN'!$E$2:$E979,B5) -> 0.64375 | F5: - | G5: =IFERROR(E5/F5,0) -> 0 | H5: =COUNTIFS('KEG. PENGAJIAN HARIAN'!$E$2:$E979,B5,'KEG. PENGAJIAN HARIAN'!$B$2:$B979,">="&$E$2,'KEG. PENGAJIAN HARIAN'!$B$2:$B979,"<="&$G$2,'KEG. PENGAJIAN HARIAN'!$G$2:$G979,"Hadir") -> 23
A6: 2 | B6: Ayu-CKP | E6: =sumifs('KEG. PENGAJIAN HARIAN'!$D$2:$D979,'KEG. PENGAJIAN HARIAN'!$B$2:$B979,">="&$E$2,'KEG. PENGAJIAN HARIAN'!$B$2:$B979,"<="&$G$2,'KEG. PENGAJIAN HARIAN'!$E$2:$E979,B6) -> 0.30138889 | F6: - | G6: =IFERROR(E6/F6,0) -> 0 | H6: =COUNTIFS('KEG. PENGAJIAN HARIAN'!$E$2:$E979,B6,'KEG. PENGAJIAN HARIAN'!$B$2:$B979,">="&$E$2,'KEG. PENGAJIAN HARIAN'!$B$2:$B979,"<="&$G$2,'KEG. PENGAJIAN HARIAN'!$G$2:$G979,"Hadir") -> 4
A7: 3 | B7: Azki-MDN | E7: =sumifs('KEG. PENGAJIAN HARIAN'!$D$2:$D979,'KEG. PENGAJIAN HARIAN'!$B$2:$B979,">="&$E$2,'KEG. PENGAJIAN HARIAN'!$B$2:$B979,"<="&$G$2,'KEG. PENGAJIAN HARIAN'!$E$2:$E979,B7) -> 0.63472222 | F7: - | G7: =IFERROR(E7/F7,0) -> 0 | H7: =COUNTIFS('KEG. PENGAJIAN HARIAN'!$E$2:$E979,B7,'KEG. PENGAJIAN HARIAN'!$B$2:$B979,">="&$E$2,'KEG. PENGAJIAN HARIAN'!$B$2:$B979,"<="&$G$2,'KEG. PENGAJIAN HARIAN'!$G$2:$G979,"Hadir") -> 11
A8: 4 | B8: Dilla-MLL | E8: =sumifs('KEG. PENGAJIAN HARIAN'!$D$2:$D979,'KEG. PENGAJIAN HARIAN'!$B$2:$B979,">="&$E$2,'KEG. PENGAJIAN HARIAN'!$B$2:$B979,"<="&$G$2,'KEG. PENGAJIAN HARIAN'!$E$2:$E979,B8) -> 1.2375 | F8: - | G8: =IFERROR(E8/F8,0) -> 0 | H8: =COUNTIFS('KEG. PENGAJIAN HARIAN'!$E$2:$E979,B8,'KEG. PENGAJIAN HARIAN'!$B$2:$B979,">="&$E$2,'KEG. PENGAJIAN HARIAN'!$B$2:$B979,"<="&$G$2,'KEG. PENGAJIAN HARIAN'!$G$2:$G979,"Hadir") -> 32
A9: 5 | B9: Erma-BKS | E9: =sumifs('KEG. PENGAJIAN HARIAN'!$D$2:$D979,'KEG. PENGAJIAN HARIAN'!$B$2:$B979,">="&$E$2,'KEG. PENGAJIAN HARIAN'!$B$2:$B979,"<="&$G$2,'KEG. PENGAJIAN HARIAN'!$E$2:$E979,B9) -> 0.30763889 | F9: - | G9: =IFERROR(E9/F9,0) -> 0 | H9: =COUNTIFS('KEG. PENGAJIAN HARIAN'!$E$2:$E979,B9,'KEG. PENGAJIAN HARIAN'!$B$2:$B979,">="&$E$2,'KEG. PENGAJIAN HARIAN'!$B$2:$B979,"<="&$G$2,'KEG. PENGAJIAN HARIAN'!$G$2:$G979,"Hadir") -> 7
A10: 6 | B10: Fadly-SMG | E10: =sumifs('KEG. PENGAJIAN HARIAN'!$D$2:$D979,'KEG. PENGAJIAN HARIAN'!$B$2:$B979,">="&$E$2,'KEG. PENGAJIAN HARIAN'!$B$2:$B979,"<="&$G$2,'KEG. PENGAJIAN HARIAN'!$E$2:$E979,B10) -> 0.32083333 | F10: - | G10: =IFERROR(E10/F10,0) -> 0 | H10: =COUNTIFS('KEG. PENGAJIAN HARIAN'!$E$2:$E979,B10,'KEG. PENGAJIAN HARIAN'!$B$2:$B979,">="&$E$2,'KEG. PENGAJIAN HARIAN'!$B$2:$B979,"<="&$G$2,'KEG. PENGAJIAN HARIAN'!$G$2:$G979,"Hadir") -> 14
A11: 7 | B11: Fauzan-SL3 | E11: =sumifs('KEG. PENGAJIAN HARIAN'!$D$2:$D979,'KEG. PENGAJIAN HARIAN'!$B$2:$B979,">="&$E$2,'KEG. PENGAJIAN HARIAN'!$B$2:$B979,"<="&$G$2,'KEG. PENGAJIAN HARIAN'!$E$2:$E979,B11) -> 0.29166667 | F11: - | G11: =IFERROR(E11/F11,0) -> 0 | H11: =COUNTIFS('KEG. PENGAJIAN HARIAN'!$E$2:$E979,B11,'KEG. PENGAJIAN HARIAN'!$B$2:$B979,">="&$E$2,'KEG. PENGAJIAN HARIAN'!$B$2:$B979,"<="&$G$2,'KEG. PENGAJIAN HARIAN'!$G$2:$G979,"Hadir") -> 12
A12: 8 | B12: Ilham-Solo | E12: =sumifs('KEG. PENGAJIAN HARIAN'!$D$2:$D979,'KEG. PENGAJIAN HARIAN'!$B$2:$B979,">="&$E$2,'KEG. PENGAJIAN HARIAN'!$B$2:$B979,"<="&$G$2,'KEG. PENGAJIAN HARIAN'!$E$2:$E979,B12) -> 0.42083333 | F12: - | G12: =IFERROR(E12/F12,0) -> 0 | H12: =COUNTIFS('KEG. PENGAJIAN HARIAN'!$E$2:$E979,B12,'KEG. PENGAJIAN HARIAN'!$B$2:$B979,">="&$E$2,'KEG. PENGAJIAN HARIAN'!$B$2:$B979,"<="&$G$2,'KEG. PENGAJIAN HARIAN'!$G$2:$G979,"Hadir") -> 11
A13: 9 | B13: Mora-MLL | E13: =sumifs('KEG. PENGAJIAN HARIAN'!$D$2:$D979,'KEG. PENGAJIAN HARIAN'!$B$2:$B979,">="&$E$2,'KEG. PENGAJIAN HARIAN'!$B$2:$B979,"<="&$G$2,'KEG. PENGAJIAN HARIAN'!$E$2:$E979,B13) -> 0.89166667 | F13: - | G13: =IFERROR(E13/F13,0) -> 0 | H13: =COUNTIFS('KEG. PENGAJIAN HARIAN'!$E$2:$E979,B13,'KEG. PENGAJIAN HARIAN'!$B$2:$B979,">="&$E$2,'KEG. PENGAJIAN HARIAN'!$B$2:$B979,"<="&$G$2,'KEG. PENGAJIAN HARIAN'!$G$2:$G979,"Hadir") -> 24
A14: 10 | B14: Naely-BGR | E14: =sumifs('KEG. PENGAJIAN HARIAN'!$D$2:$D979,'KEG. PENGAJIAN HARIAN'!$B$2:$B979,">="&$E$2,'KEG. PENGAJIAN HARIAN'!$B$2:$B979,"<="&$G$2,'KEG. PENGAJIAN HARIAN'!$E$2:$E979,B14) -> 0.53611111 | F14: - | G14: =IFERROR(E14/F14,0) -> 0 | H14: =COUNTIFS('KEG. PENGAJIAN HARIAN'!$E$2:$E979,B14,'KEG. PENGAJIAN HARIAN'!$B$2:$B979,">="&$E$2,'KEG. PENGAJIAN HARIAN'!$B$2:$B979,"<="&$G$2,'KEG. PENGAJIAN HARIAN'!$G$2:$G979,"Hadir") -> 19
A15: 11 | B15: Rika-KDR | E15: =sumifs('KEG. PENGAJIAN HARIAN'!$D$2:$D979,'KEG. PENGAJIAN HARIAN'!$B$2:$B979,">="&$E$2,'KEG. PENGAJIAN HARIAN'!$B$2:$B979,"<="&$G$2,'KEG. PENGAJIAN HARIAN'!$E$2:$E979,B15) -> 0.097916667 | F15: - | G15: =IFERROR(E15/F15,0) -> 0 | H15: =COUNTIFS('KEG. PENGAJIAN HARIAN'!$E$2:$E979,B15,'KEG. PENGAJIAN HARIAN'!$B$2:$B979,">="&$E$2,'KEG. PENGAJIAN HARIAN'!$B$2:$B979,"<="&$G$2,'KEG. PENGAJIAN HARIAN'!$G$2:$G979,"Hadir") -> 5
A18: REKAPITULASI KEHADIRAN MURID PENGAJIAN PPG AMERICA
A19: 45292
A21: NO. | B21: NAMA MURID | C21: KELOMPOK | D21: KELAS | E21: DURASI MENGAJI | F21: TARGET DURASI | G21: % DURASI | H21: JUMLAH PERTEMUAN | I21: KETERANGAN | J21: KET.
A22: 1 | B22: Abi-BFL | C22: Chicago | D22: PraNiKah | E22: =sumifs('KEG. PENGAJIAN HARIAN'!$D$2:$D979,'KEG. PENGAJIAN HARIAN'!$B$2:$B979,">="&$E$2,'KEG. PENGAJIAN HARIAN'!$B$2:$B979,"<="&$G$2,'KEG. PENGAJIAN HARIAN'!$F$2:$F979,B22) -> 0.3375 | F22: 0.5 | G22: =IFERROR(E22/F22,0) -> 0.675 | H22: =COUNTIFS('KEG. PENGAJIAN HARIAN'!$F$2:$F979,B22,'KEG. PENGAJIAN HARIAN'!$B$2:$B979,">="&$E$2,'KEG. PENGAJIAN HARIAN'!$B$2:$B979,"<="&$G$2,'KEG. PENGAJIAN HARIAN'!$G$2:$G979,"hadir") -> 7 | L22: PraCBR-CBR | M22: =countif(D22:D42,"PraCBR-CBR") -> 10
A23: 2 | B23: AJ-CA | C23: California | D23: PraNiKah | E23: =sumifs('KEG. PENGAJIAN HARIAN'!$D$2:$D979,'KEG. PENGAJIAN HARIAN'!$B$2:$B979,">="&$E$2,'KEG. PENGAJIAN HARIAN'!$B$2:$B979,"<="&$G$2,'KEG. PENGAJIAN HARIAN'!$F$2:$F979,B23) -> 0 | F23: 0.5 | G23: =IFERROR(E23/F23,0) -> 0 | H23: =COUNTIFS('KEG. PENGAJIAN HARIAN'!$F$2:$F979,B23,'KEG. PENGAJIAN HARIAN'!$B$2:$B979,">="&$E$2,'KEG. PENGAJIAN HARIAN'!$B$2:$B979,"<="&$G$2,'KEG. PENGAJIAN HARIAN'!$G$2:$G979,"hadir") -> 0 | L23: PraRMJ-RMJ | M23: =countif(D22:D42,"PraRMJ-RMJ") -> 7
A24: 3 | B24: Chester-PD | C24: New Hampshire | D24: PraCBR-CBR | E24: =sumifs('KEG. PENGAJIAN HARIAN'!$D$2:$D979,'KEG. PENGAJIAN HARIAN'!$B$2:$B979,">="&$E$2,'KEG. PENGAJIAN HARIAN'!$B$2:$B979,"<="&$G$2,'KEG. PENGAJIAN HARIAN'!$F$2:$F979,B24) -> 0.37013889 | F24: 0.5 | G24: =IFERROR(E24/F24,0) -> 0.74027778 | H24: =COUNTIFS('KEG. PENGAJIAN HARIAN'!$F$2:$F979,B24,'KEG. PENGAJIAN HARIAN'!$B$2:$B979,">="&$E$2,'KEG. PENGAJIAN HARIAN'!$B$2:$B979,"<="&$G$2,'KEG. PENGAJIAN HARIAN'!$G$2:$G979,"hadir") -> 8 | L24: PraNIkah | M24: =countif(D22:D43,"PraNikah") -> 4
A25: 4 | B25: Dawud-RLG | C25: New Hampshire | D25: PraCBR-CBR | E25: =sumifs('KEG. PENGAJIAN HARIAN'!$D$2:$D979,'KEG. PENGAJIAN HARIAN'!$B$2:$B979,">="&$E$2,'KEG. PENGAJIAN HARIAN'!$B$2:$B979,"<="&$G$2,'KEG. PENGAJIAN HARIAN'!$F$2:$F979,B25) -> 0.16875 | F25: 0.5 | G25: =IFERROR(E25/F25,0) -> 0.3375 | H25: =COUNTIFS('KEG. PENGAJIAN HARIAN'!$F$2:$F979,B25,'KEG. PENGAJIAN HARIAN'!$B$2:$B979,">="&$E$2,'KEG. PENGAJIAN HARIAN'!$B$2:$B979,"<="&$G$2,'KEG. PENGAJIAN HARIAN'!$G$2:$G979,"hadir") -> 5
A26: 5 | B26: Dehan-CND | C26: Canada | D26: PraRMJ-RMJ | E26: =sumifs('KEG. PENGAJIAN HARIAN'!$D$2:$D979,'KEG. PENGAJIAN HARIAN'!$B$2:$B979,">="&$E$2,'KEG. PENGAJIAN HARIAN'!$B$2:$B979,"<="&$G$2,'KEG. PENGAJIAN HARIAN'!$F$2:$F979,B26) -> 0.11944444 | F26: 0.5 | G26: =IFERROR(E26/F26,0) -> 0.23888889 | H26: =COUNTIFS('KEG. PENGAJIAN HARIAN'!$F$2:$F979,B26,'KEG. PENGAJIAN HARIAN'!$B$2:$B979,">="&$E$2,'KEG. PENGAJIAN HARIAN'!$B$2:$B979,"<="&$G$2,'KEG. PENGAJIAN HARIAN'!$G$2:$G979,"hadir") -> 4 | L26: Chicago | M26: =countif(C22:C42,"Chicago") -> 10 | N26: =sumif(C22:C42,"Chicago",F22:F42) -> 5
A27: 6 | B27: Denissa-RLG | C27: New Hampshire | D27: PraRMJ-RMJ | E27: =sumifs('KEG. PENGAJIAN HARIAN'!$D$2:$D979,'KEG. PENGAJIAN HARIAN'!$B$2:$B979,">="&$E$2,'KEG. PENGAJIAN HARIAN'!$B$2:$B979,"<="&$G$2,'KEG. PENGAJIAN HARIAN'!$F$2:$F979,B27) -> 0.16736111 | F27: 0.5 | G27: =IFERROR(E27/F27,0) -> 0.33472222 | H27: =COUNTIFS('KEG. PENGAJIAN HARIAN'!$F$2:$F979,B27,'KEG. PENGAJIAN HARIAN'!$B$2:$B979,">="&$E$2,'KEG. PENGAJIAN HARIAN'!$B$2:$B979,"<="&$G$2,'KEG. PENGAJIAN HARIAN'!$G$2:$G979,"hadir") -> 3 | L27: California | M27: =countif(C22:C42,"California") -> 4 | N27: =sumif(C22:C42,"California",F22:F42) -> 2
A28: 7 | B28: Dinda-RLG | C28: New Hampshire | D28: PraCBR-CBR | E28: =sumifs('KEG. PENGAJIAN HARIAN'!$D$2:$D979,'KEG. PENGAJIAN HARIAN'!$B$2:$B979,">="&$E$2,'KEG. PENGAJIAN HARIAN'!$B$2:$B979,"<="&$G$2,'KEG. PENGAJIAN HARIAN'!$F$2:$F979,B28) -> 0.21527778 | F28: 0.5 | G28: =IFERROR(E28/F28,0) -> 0.43055556 | H28: =COUNTIFS('KEG. PENGAJIAN HARIAN'!$F$2:$F979,B28,'KEG. PENGAJIAN HARIAN'!$B$2:$B979,">="&$E$2,'KEG. PENGAJIAN HARIAN'!$B$2:$B979,"<="&$G$2,'KEG. PENGAJIAN HARIAN'!$G$2:$G979,"hadir") -> 5 | L28: New Hampshire | M28: =countif(C22:C42,"New Hampshire") -> 5 | N28: =sumif(C22:C42,"New Hampshire",F22:F42) -> 2.5
A29: 8 | B29: Dwiki-RLG | C29: New Hampshire | D29: PraRMJ-RMJ | E29: =sumifs('KEG. PENGAJIAN HARIAN'!$D$2:$D979,'KEG. PENGAJIAN HARIAN'!$B$2:$B979,">="&$E$2,'KEG. PENGAJIAN HARIAN'!$B$2:$B979,"<="&$G$2,'KEG. PENGAJIAN HARIAN'!$F$2:$F979,B29) -> 0.081944444 | F29: 0.5 | G29: =IFERROR(E29/F29,0) -> 0.16388889 | H29: =COUNTIFS('KEG. PENGAJIAN HARIAN'!$F$2:$F979,B29,'KEG. PENGAJIAN HARIAN'!$B$2:$B979,">="&$E$2,'KEG. PENGAJIAN HARIAN'!$B$2:$B979,"<="&$G$2,'KEG. PENGAJIAN HARIAN'!$G$2:$G979,"hadir") -> 3 | L29: Canada | M29: =countif(C24:C44,"Canada") -> 2 | N29: =sumif(C22:C42,"Canada",F22:F42) -> 1
A30: 9 | B30: Dylan-CA | C30: California | D30: PraRMJ-RMJ | E30: =sumifs('KEG. PENGAJIAN HARIAN'!$D$2:$D979,'KEG. PENGAJIAN HARIAN'!$B$2:$B979,">="&$E$2,'KEG. PENGAJIAN HARIAN'!$B$2:$B979,"<="&$G$2,'KEG. PENGAJIAN HARIAN'!$F$2:$F979,B30) -> 0.21736111 | F30: 0.5 | G30: =IFERROR(E30/F30,0) -> 0.43472222 | H30: =COUNTIFS('KEG. PENGAJIAN HARIAN'!$F$2:$F979,B30,'KEG. PENGAJIAN HARIAN'!$B$2:$B979,">="&$E$2,'KEG. PENGAJIAN HARIAN'!$B$2:$B979,"<="&$G$2,'KEG. PENGAJIAN HARIAN'!$G$2:$G979,"hadir") -> 10
A31: 10 | B31: Fitri-CND | C31: Canada | D31: PraRMJ-RMJ | E31: =sumifs('KEG. PENGAJIAN HARIAN'!$D$2:$D979,'KEG. PENGAJIAN HARIAN'!$B$2:$B979,">="&$E$2,'KEG. PENGAJIAN HARIAN'!$B$2:$B979,"<="&$G$2,'KEG. PENGAJIAN HARIAN'!$F$2:$F979,B31) -> 0.42291667 | F31: 0.5 | G31: =IFERROR(E31/F31,0) -> 0.84583333 | H31: =COUNTIFS('KEG. PENGAJIAN HARIAN'!$F$2:$F979,B31,'KEG. PENGAJIAN HARIAN'!$B$2:$B979,">="&$E$2,'KEG. PENGAJIAN HARIAN'!$B$2:$B979,"<="&$G$2,'KEG. PENGAJIAN HARIAN'!$G$2:$G979,"hadir") -> 7
A32: 11 | B32: Gabriel-CH | C32: Chicago | D32: PraCBR-CBR | E32: =sumifs('KEG. PENGAJIAN HARIAN'!$D$2:$D979,'KEG. PENGAJIAN HARIAN'!$B$2:$B979,">="&$E$2,'KEG. PENGAJIAN HARIAN'!$B$2:$B979,"<="&$G$2,'KEG. PENGAJIAN HARIAN'!$F$2:$F979,B32) -> 0.32083333 | F32: 0.5 | G32: =IFERROR(E32/F32,0) -> 0.64166667 | H32: =COUNTIFS('KEG. PENGAJIAN HARIAN'!$F$2:$F979,B32,'KEG. PENGAJIAN HARIAN'!$B$2:$B979,">="&$E$2,'KEG. PENGAJIAN HARIAN'!$B$2:$B979,"<="&$G$2,'KEG. PENGAJIAN HARIAN'!$G$2:$G979,"hadir") -> 14
A33: 12 | B33: Grazia-IN | C33: Chicago | D33: PraCBR-CBR | E33: =sumifs('KEG. PENGAJIAN HARIAN'!$D$2:$D979,'KEG. PENGAJIAN HARIAN'!$B$2:$B979,">="&$E$2,'KEG. PENGAJIAN HARIAN'!$B$2:$B979,"<="&$G$2,'KEG. PENGAJIAN HARIAN'!$F$2:$F979,B33) -> 0.69583333 | F33: 0.5 | G33: =IFERROR(E33/F33,0) -> 1.3916667 | H33: =COUNTIFS('KEG. PENGAJIAN HARIAN'!$F$2:$F979,B33,'KEG. PENGAJIAN HARIAN'!$B$2:$B979,">="&$E$2,'KEG. PENGAJIAN HARIAN'!$B$2:$B979,"<="&$G$2,'KEG. PENGAJIAN HARIAN'!$G$2:$G979,"hadir") -> 16
A34: 13 | B34: Irsan-CH | C34: Chicago | D34: PraRMJ-RMJ | E34: =sumifs('KEG. PENGAJIAN HARIAN'!$D$2:$D979,'KEG. PENGAJIAN HARIAN'!$B$2:$B979,">="&$E$2,'KEG. PENGAJIAN HARIAN'!$B$2:$B979,"<="&$G$2,'KEG. PENGAJIAN HARIAN'!$F$2:$F979,B34) -> 0.175 | F34: 0.5 | G34: =IFERROR(E34/F34,0) -> 0.35 | H34: =COUNTIFS('KEG. PENGAJIAN HARIAN'!$F$2:$F979,B34,'KEG. PENGAJIAN HARIAN'!$B$2:$B979,">="&$E$2,'KEG. PENGAJIAN HARIAN'!$B$2:$B979,"<="&$G$2,'KEG. PENGAJIAN HARIAN'!$G$2:$G979,"hadir") -> 9
A35: 14 | B35: Jourdan-CA | C35: California | D35: PraNiKah | E35: =sumifs('KEG. PENGAJIAN HARIAN'!$D$2:$D979,'KEG. PENGAJIAN HARIAN'!$B$2:$B979,">="&$E$2,'KEG. PENGAJIAN HARIAN'!$B$2:$B979,"<="&$G$2,'KEG. PENGAJIAN HARIAN'!$F$2:$F979,B35) -> 0.088194444 | F35: 0.5 | G35: =IFERROR(E35/F35,0) -> 0.17638889 | H35: =COUNTIFS('KEG. PENGAJIAN HARIAN'!$F$2:$F979,B35,'KEG. PENGAJIAN HARIAN'!$B$2:$B979,">="&$E$2,'KEG. PENGAJIAN HARIAN'!$B$2:$B979,"<="&$G$2,'KEG. PENGAJIAN HARIAN'!$G$2:$G979,"hadir") -> 2
A36: 15 | B36: Jubilee-CH | C36: Chicago | D36: PraCBR-CBR | E36: =sumifs('KEG. PENGAJIAN HARIAN'!$D$2:$D979,'KEG. PENGAJIAN HARIAN'!$B$2:$B979,">="&$E$2,'KEG. PENGAJIAN HARIAN'!$B$2:$B979,"<="&$G$2,'KEG. PENGAJIAN HARIAN'!$F$2:$F979,B36) -> 0.32361111 | F36: 0.5 | G36: =IFERROR(E36/F36,0) -> 0.64722222 | H36: =COUNTIFS('KEG. PENGAJIAN HARIAN'!$F$2:$F979,B36,'KEG. PENGAJIAN HARIAN'!$B$2:$B979,">="&$E$2,'KEG. PENGAJIAN HARIAN'!$B$2:$B979,"<="&$G$2,'KEG. PENGAJIAN HARIAN'!$G$2:$G979,"hadir") -> 10
A37: 16 | B37: Kayla-CA | C37: California | D37: PraNiKah | E37: =sumifs('KEG. PENGAJIAN HARIAN'!$D$2:$D979,'KEG. PENGAJIAN HARIAN'!$B$2:$B979,">="&$E$2,'KEG. PENGAJIAN HARIAN'!$B$2:$B979,"<="&$G$2,'KEG. PENGAJIAN HARIAN'!$F$2:$F979,B37) -> 0.58611111 | F37: 0.5 | G37: =IFERROR(E37/F37,0) -> 1.1722222 | H37: =COUNTIFS('KEG. PENGAJIAN HARIAN'!$F$2:$F979,B37,'KEG. PENGAJIAN HARIAN'!$B$2:$B979,">="&$E$2,'KEG. PENGAJIAN HARIAN'!$B$2:$B979,"<="&$G$2,'KEG. PENGAJIAN HARIAN'!$G$2:$G979,"hadir") -> 9
A38: 17 | B38: Kirana-CH | C38: Chicago | D38: PraCBR-CBR | E38: =sumifs('KEG. PENGAJIAN HARIAN'!$D$2:$D979,'KEG. PENGAJIAN HARIAN'!$B$2:$B979,">="&$E$2,'KEG. PENGAJIAN HARIAN'!$B$2:$B979,"<="&$G$2,'KEG. PENGAJIAN HARIAN'!$F$2:$F979,B38) -> 0.31944444 | F38: 0.5 | G38: =IFERROR(E38/F38,0) -> 0.63888889 | H38: =COUNTIFS('KEG. PENGAJIAN HARIAN'!$F$2:$F979,B38,'KEG. PENGAJIAN HARIAN'!$B$2:$B979,">="&$E$2,'KEG. PENGAJIAN HARIAN'!$B$2:$B979,"<="&$G$2,'KEG. PENGAJIAN HARIAN'!$G$2:$G979,"hadir") -> 13
A39: 18 | B39: Mikail-CH | C39: Chicago | D39: PraCBR-CBR | E39: =sumifs('KEG. PENGAJIAN HARIAN'!$D$2:$D979,'KEG. PENGAJIAN HARIAN'!$B$2:$B979,">="&$E$2,'KEG. PENGAJIAN HARIAN'!$B$2:$B979,"<="&$G$2,'KEG. PENGAJIAN HARIAN'!$F$2:$F979,B39) -> 0.30416667 | F39: 0.5 | G39: =IFERROR(E39/F39,0) -> 0.60833333 | H39: =COUNTIFS('KEG. PENGAJIAN HARIAN'!$F$2:$F979,B39,'KEG. PENGAJIAN HARIAN'!$B$2:$B979,">="&$E$2,'KEG. PENGAJIAN HARIAN'!$B$2:$B979,"<="&$G$2,'KEG. PENGAJIAN HARIAN'!$G$2:$G979,"hadir") -> 13
A40: 19 | B40: Nadeen-CH | C40: Chicago | D40: PraCBR-CBR | E40: =sumifs('KEG. PENGAJIAN HARIAN'!$D$2:$D979,'KEG. PENGAJIAN HARIAN'!$B$2:$B979,">="&$E$2,'KEG. PENGAJIAN HARIAN'!$B$2:$B979,"<="&$G$2,'KEG. PENGAJIAN HARIAN'!$F$2:$F979,B40) -> 0.30902778 | F40: 0.5 | G40: =IFERROR(E40/F40,0) -> 0.61805556 | H40: =COUNTIFS('KEG. PENGAJIAN HARIAN'!$F$2:$F979,B40,'KEG. PENGAJIAN HARIAN'!$B$2:$B979,">="&$E$2,'KEG. PENGAJIAN HARIAN'!$B$2:$B979,"<="&$G$2,'KEG. PENGAJIAN HARIAN'!$G$2:$G979,"hadir") -> 16
A41: 20 | B41: Qalesya-ATL | C41: Chicago | D41: PraCBR-CBR | E41: =sumifs('KEG. PENGAJIAN HARIAN'!$D$2:$D979,'KEG. PENGAJIAN HARIAN'!$B$2:$B979,">="&$E$2,'KEG. PENGAJIAN HARIAN'!$B$2:$B979,"<="&$G$2,'KEG. PENGAJIAN HARIAN'!$F$2:$F979,B41) -> 0.033333333 | F41: 0.5 | G41: =IFERROR(E41/F41,0) -> 0.066666667 | H41: =COUNTIFS('KEG. PENGAJIAN HARIAN'!$F$2:$F979,B41,'KEG. PENGAJIAN HARIAN'!$B$2:$B979,">="&$E$2,'KEG. PENGAJIAN HARIAN'!$B$2:$B979,"<="&$G$2,'KEG. PENGAJIAN HARIAN'!$G$2:$G979,"hadir") -> 1
A42: 21 | B42: Tami-BFL | C42: Chicago | D42: PraRMJ-RMJ | E42: =sumifs('KEG. PENGAJIAN HARIAN'!$D$2:$D979,'KEG. PENGAJIAN HARIAN'!$B$2:$B979,">="&$E$2,'KEG. PENGAJIAN HARIAN'!$B$2:$B979,"<="&$G$2,'KEG. PENGAJIAN HARIAN'!$F$2:$F979,B42) -> 0.51805556 | F42: 0.5 | G42: =IFERROR(E42/F42,0) -> 1.0361111 | H42: =COUNTIFS('KEG. PENGAJIAN HARIAN'!$F$2:$F979,B42,'KEG. PENGAJIAN HARIAN'!$B$2:$B979,">="&$E$2,'KEG. PENGAJIAN HARIAN'!$B$2:$B979,"<="&$G$2,'KEG. PENGAJIAN HARIAN'!$G$2:$G979,"hadir") -> 9
E43: =SUM(E22:E42) -> 5.7743056 | F43: =SUM(F22:F42) -> 10.5
B44: % per bulan | E44: =E43/F43 -> 0.54993386
...

Sheet Februari
A1: REKAPITULASI KEHADIRAN GURU MENGAJAR - PENGAJIAN PPG US
B2: Mulai : | E2: 45323 | F2: Hingga : | G2: 45351
A4: NO. | B4: NAMA GURU | E4: DURASI MENGAJI | F4: TARGET DURASI | G4: % DURASI | H4: JUMLAH PERTEMUAN | Q4: February 14, 2024 1:49 pm | R4: 45336 | S4: 0.052083333 | T4: Dilla-MLL | U4: Tami-BFL | V4: HADIR | W4: 1. Bacaan Al ankabut 24-30 Alkhamdulillah lancar bacaannya dan juga teratur lebih improve pernafasan nya aja 2. Makna Al baqoroh 89-92 Allah lancar juga and in syaa Alloh Tami faham apa yang disampaikan Dilla Semoga Tami kelak juga bisa menyampaikan ilmunya disana alias jadi sarjana yang mubaligh,Aamiin..aamiin May Alloh Bless you and see u next meeting | X4: 6281392827981 | Y4: 6281392827981
A5: 1 | B5: Artha-JG | E5: =sumifs('KEG. PENGAJIAN HARIAN'!$D$2:$D979,'KEG. PENGAJIAN HARIAN'!$B$2:$B979,">="&$E$2,'KEG. PENGAJIAN HARIAN'!$B$2:$B979,"<="&$G$2,'KEG. PENGAJIAN HARIAN'!$E$2:$E979,B5) -> 0.89513889 | F5: - | G5: =IFERROR(E5/F5,0) -> 0 | H5: =COUNTIFS('KEG. PENGAJIAN HARIAN'!$E$2:$E979,B5,'KEG. PENGAJIAN HARIAN'!$B$2:$B979,">="&$E$2,'KEG. PENGAJIAN HARIAN'!$B$2:$B979,"<="&$G$2,'KEG. PENGAJIAN HARIAN'!$G$2:$G979,"Hadir") -> 29 | Q5: February 14, 2024 1:48 pm | R5: 45336 | S5: 0.026388889 | T5: Mora-MLL | U5: Dylan-CA | V5: HADIR | W5: A. Bacaan Al-A'raf ayat 96-104 Alkhamdulillah lancar. Diperlancar untuk pernafasan dan pemenggalan kata. B. Makna k.sholah hal. 12-13 Dylan bisa memahami isi hadist dg baik. | X5: 6285173431354 | Y5: 6285173431354
A6: 2 | B6: Ayu-CKP | E6: =sumifs('KEG. PENGAJIAN HARIAN'!$D$2:$D979,'KEG. PENGAJIAN HARIAN'!$B$2:$B979,">="&$E$2,'KEG. PENGAJIAN HARIAN'!$B$2:$B979,"<="&$G$2,'KEG. PENGAJIAN HARIAN'!$E$2:$E979,B6) -> 0.19236111 | F6: - | G6: =IFERROR(E6/F6,0) -> 0 | H6: =COUNTIFS('KEG. PENGAJIAN HARIAN'!$E$2:$E979,B6,'KEG. PENGAJIAN HARIAN'!$B$2:$B979,">="&$E$2,'KEG. PENGAJIAN HARIAN'!$B$2:$B979,"<="&$G$2,'KEG. PENGAJIAN HARIAN'!$G$2:$G979,"Hadir") -> 3 | Q6: February 14, 2024 2:24 pm | R6: 45336 | S6: 0.034027778 | T6: Artha-JG | U6: Dwiki-RLG | V6: HADIR | W6: Bacaan Surat Jin ayat 21-28 & surat al muzzammil ayat 1-19 Tebak2 an tajwid beserta huruf hurufnya Makna surat al an'am 145 Report Untuk bacaan, alhamdulillah Dwiki sudah bagus tp dengungnya kurang tampak,terlihat ketika ada bacaan ikhfa' hakiki, ikhfa' safawi, gunnah musaddah . Untuk tajwidmungkin karna lama nggak ngaji jadi ada beberapa yg lupa. Kalau untuk makna Alhamdulillah bisa mengikuti dg baik. Tetap semangat ngaji ya Dwiki💪semoga Alloh paring manfaat dan barokah aamiiin🤲 | X6: 6285606274880 | Y6: 6285606274880
A7: 3 | B7: Azki-MDN | E7: =sumifs('KEG. PENGAJIAN HARIAN'!$D$2:$D979,'KEG. PENGAJIAN HARIAN'!$B$2:$B979,">="&$E$2,'KEG. PENGAJIAN HARIAN'!$B$2:$B979,"<="&$G$2,'KEG. PENGAJIAN HARIAN'!$E$2:$E979,B7) -> 0.46180556 | F7: - | G7: =IFERROR(E7/F7,0) -> 0 | H7: =COUNTIFS('KEG. PENGAJIAN HARIAN'!$E$2:$E979,B7,'KEG. PENGAJIAN HARIAN'!$B$2:$B979,">="&$E$2,'KEG. PENGAJIAN HARIAN'!$B$2:$B979,"<="&$G$2,'KEG. PENGAJIAN HARIAN'!$G$2:$G979,"Hadir") -> 8 | Q7: February 14, 2024 2:41 pm | R7: 45336 | S7: 0.021527778 | T7: Fadly-SMG | U7: Gabriel-CH | V7: HADIR | W7: - Tilawati 3 hal 41 - Murojaah surat2 pendek dan doa2 harian Semoga Allah Paring manfaat lancar dan barokah | X7: 6281332534354 | Y7: 6281332534354
A8: 4 | B8: Dilla-MLL | E8: =sumifs('KEG. PENGAJIAN HARIAN'!$D$2:$D979,'KEG. PENGAJIAN HARIAN'!$B$2:$B979,">="&$E$2,'KEG. PENGAJIAN HARIAN'!$B$2:$B979,"<="&$G$2,'KEG. PENGAJIAN HARIAN'!$E$2:$E979,B8) -> 0.90416667 | F8: - | G8: =IFERROR(E8/F8,0) -> 0 | H8: =COUNTIFS('KEG. PENGAJIAN HARIAN'!$E$2:$E979,B8,'KEG. PENGAJIAN HARIAN'!$B$2:$B979,">="&$E$2,'KEG. PENGAJIAN HARIAN'!$B$2:$B979,"<="&$G$2,'KEG. PENGAJIAN HARIAN'!$G$2:$G979,"Hadir") -> 28 | Q8: February 14, 2024 1:57 pm | R8: 45336 | S8: 0.026388889 | T8: Naely-BGR | U8: Mikail-CH | V8: HADIR | W8: 1. baca tilawati 4 hal.35 alhamdulillah lancar bisa mengikuti dengan baik 2. baca surat2 pilihan surat al hasyr beserta ta'awudz alhamdulillah bisa membaca dengan baik dan lancar 3. menjelaskan kefadholan surat al hasyr 4. menulis etiquette during meals no.18-19 | X8: 6281269229406 | Y8: 6281269229406
A9: 5 | B9: Erma-BKS | E9: =sumifs('KEG. PENGAJIAN HARIAN'!$D$2:$D979,'KEG. PENGAJIAN HARIAN'!$B$2:$B979,">="&$E$2,'KEG. PENGAJIAN HARIAN'!$B$2:$B979,"<="&$G$2,'KEG. PENGAJIAN HARIAN'!$E$2:$E979,B9) -> 0.036805556 | F9: - | G9: =IFERROR(E9/F9,0) -> 0 | H9: =COUNTIFS('KEG. PENGAJIAN HARIAN'!$E$2:$E979,B9,'KEG. PENGAJIAN HARIAN'!$B$2:$B979,">="&$E$2,'KEG. PENGAJIAN HARIAN'!$B$2:$B979,"<="&$G$2,'KEG. PENGAJIAN HARIAN'!$G$2:$G979,"Hadir") -> 1
A10: 6 | B10: Fadly-SMG | E10: =sumifs('KEG. PENGAJIAN HARIAN'!$D$2:$D979,'KEG. PENGAJIAN HARIAN'!$B$2:$B979,">="&$E$2,'KEG. PENGAJIAN HARIAN'!$B$2:$B979,"<="&$G$2,'KEG. PENGAJIAN HARIAN'!$E$2:$E979,B10) -> 0.33125 | F10: - | G10: =IFERROR(E10/F10,0) -> 0 | H10: =COUNTIFS('KEG. PENGAJIAN HARIAN'!$E$2:$E979,B10,'KEG. PENGAJIAN HARIAN'!$B$2:$B979,">="&$E$2,'KEG. PENGAJIAN HARIAN'!$B$2:$B979,"<="&$G$2,'KEG. PENGAJIAN HARIAN'!$G$2:$G979,"Hadir") -> 14
A11: 7 | B11: Fauzan-SL3 | E11: =sumifs('KEG. PENGAJIAN HARIAN'!$D$2:$D979,'KEG. PENGAJIAN HARIAN'!$B$2:$B979,">="&$E$2,'KEG. PENGAJIAN HARIAN'!$B$2:$B979,"<="&$G$2,'KEG. PENGAJIAN HARIAN'!$E$2:$E979,B11) -> 0.26736111 | F11: - | G11: =IFERROR(E11/F11,0) -> 0 | H11: =COUNTIFS('KEG. PENGAJIAN HARIAN'!$E$2:$E979,B11,'KEG. PENGAJIAN HARIAN'!$B$2:$B979,">="&$E$2,'KEG. PENGAJIAN HARIAN'!$B$2:$B979,"<="&$G$2,'KEG. PENGAJIAN HARIAN'!$G$2:$G979,"Hadir") -> 11
A12: 8 | B12: Ilham-Solo | E12: =sumifs('KEG. PENGAJIAN HARIAN'!$D$2:$D979,'KEG. PENGAJIAN HARIAN'!$B$2:$B979,">="&$E$2,'KEG. PENGAJIAN HARIAN'!$B$2:$B979,"<="&$G$2,'KEG. PENGAJIAN HARIAN'!$E$2:$E979,B12) -> 0.31805556 | F12: - | G12: =IFERROR(E12/F12,0) -> 0 | H12: =COUNTIFS('KEG. PENGAJIAN HARIAN'!$E$2:$E979,B12,'KEG. PENGAJIAN HARIAN'!$B$2:$B979,">="&$E$2,'KEG. PENGAJIAN HARIAN'!$B$2:$B979,"<="&$G$2,'KEG. PENGAJIAN HARIAN'!$G$2:$G979,"Hadir") -> 8
A13: 9 | B13: Mora-MLL | E13: =sumifs('KEG. PENGAJIAN HARIAN'!$D$2:$D979,'KEG. PENGAJIAN HARIAN'!$B$2:$B979,">="&$E$2,'KEG. PENGAJIAN HARIAN'!$B$2:$B979,"<="&$G$2,'KEG. PENGAJIAN HARIAN'!$E$2:$E979,B13) -> 1.0527778 | F13: - | G13: =IFERROR(E13/F13,0) -> 0 | H13: =COUNTIFS('KEG. PENGAJIAN HARIAN'!$E$2:$E979,B13,'KEG. PENGAJIAN HARIAN'!$B$2:$B979,">="&$E$2,'KEG. PENGAJIAN HARIAN'!$B$2:$B979,"<="&$G$2,'KEG. PENGAJIAN HARIAN'!$G$2:$G979,"Hadir") -> 34
A14: 10 | B14: Naely-BGR | E14: =sumifs('KEG. PENGAJIAN HARIAN'!$D$2:$D979,'KEG. PENGAJIAN HARIAN'!$B$2:$B979,">="&$E$2,'KEG. PENGAJIAN HARIAN'!$B$2:$B979,"<="&$G$2,'KEG. PENGAJIAN HARIAN'!$E$2:$E979,B14) -> 0.45694444 | F14: - | G14: =IFERROR(E14/F14,0) -> 0 | H14: =COUNTIFS('KEG. PENGAJIAN HARIAN'!$E$2:$E979,B14,'KEG. PENGAJIAN HARIAN'!$B$2:$B979,">="&$E$2,'KEG. PENGAJIAN HARIAN'!$B$2:$B979,"<="&$G$2,'KEG. PENGAJIAN HARIAN'!$G$2:$G979,"Hadir") -> 17
A15: 11 | B15: Rika-KDR | E15: =sumifs('KEG. PENGAJIAN HARIAN'!$D$2:$D979,'KEG. PENGAJIAN HARIAN'!$B$2:$B979,">="&$E$2,'KEG. PENGAJIAN HARIAN'!$B$2:$B979,"<="&$G$2,'KEG. PENGAJIAN HARIAN'!$E$2:$E979,B15) -> 0.31805556 | F15: - | G15: =IFERROR(E15/F15,0) -> 0 | H15: =COUNTIFS('KEG. PENGAJIAN HARIAN'!$E$2:$E979,B15,'KEG. PENGAJIAN HARIAN'!$B$2:$B979,">="&$E$2,'KEG. PENGAJIAN HARIAN'!$B$2:$B979,"<="&$G$2,'KEG. PENGAJIAN HARIAN'!$G$2:$G979,"Hadir") -> 14
A18: REKAPITULASI KEHADIRAN MURID PENGAJIAN PPG AMERICA
A19: 45323
A21: NO. | B21: NAMA MURID | C21: KELOMPOK | D21: KELAS USIA | E21: DURASI MENGAJI | F21: TARGET DURASI | G21: % DURASI | H21: HADIR | I21: BY VN | J21: IZIN (MURID)
A22: 1 | B22: Abi-BFL | C22: Chicago | D22: PraNiKah | E22: =sumifs('KEG. PENGAJIAN HARIAN'!$D$2:$D979,'KEG. PENGAJIAN HARIAN'!$B$2:$B979,">="&$E$2,'KEG. PENGAJIAN HARIAN'!$B$2:$B979,"<="&$G$2,'KEG. PENGAJIAN HARIAN'!$F$2:$F979,B22) -> 0.36597222 | F22: 0.5 | G22: =IFERROR(E22/F22,0) -> 0.73194444 | H22: =COUNTIFS('KEG. PENGAJIAN HARIAN'!$F$2:$F979,B22,'KEG. PENGAJIAN HARIAN'!$B$2:$B979,">="&$E$2,'KEG. PENGAJIAN HARIAN'!$B$2:$B979,"<="&$G$2,'KEG. PENGAJIAN HARIAN'!$G$2:$G979,"hadir") -> 9 | I22: =COUNTIFS('KEG. PENGAJIAN HARIAN'!$F$2:$F979,B22,'KEG. PENGAJIAN HARIAN'!$B$2:$B979,">="&$E$2,'KEG. PENGAJIAN HARIAN'!$B$2:$B979,"<="&$G$2,'KEG. PENGAJIAN HARIAN'!$G$2:$G979,"By VN") -> 0 | J22: =COUNTIFS('KEG. PENGAJIAN HARIAN'!$F$2:$F979,B22,'KEG. PENGAJIAN HARIAN'!$B$2:$B979,">="&$E$2,'KEG. PENGAJIAN HARIAN'!$B$2:$B979,"<="&$G$2,'KEG. PENGAJIAN HARIAN'!$G$2:$G979,"izin (murid)") -> 0 | K22: PraCBR-CBR | L22: =countif(D22:D42,"PraCBR-CBR") -> 10
A23: 2 | B23: AJ-CA | C23: California | D23: PraNiKah | E23: =sumifs('KEG. PENGAJIAN HARIAN'!$D$2:$D979,'KEG. PENGAJIAN HARIAN'!$B$2:$B979,">="&$E$2,'KEG. PENGAJIAN HARIAN'!$B$2:$B979,"<="&$G$2,'KEG. PENGAJIAN HARIAN'!$F$2:$F979,B23) -> 0 | F23: 0.5 | G23: =IFERROR(E23/F23,0) -> 0 | H23: =COUNTIFS('KEG. PENGAJIAN HARIAN'!$F$2:$F979,B23,'KEG. PENGAJIAN HARIAN'!$B$2:$B979,">="&$E$2,'KEG. PENGAJIAN HARIAN'!$B$2:$B979,"<="&$G$2,'KEG. PENGAJIAN HARIAN'!$G$2:$G979,"hadir") -> 0 | I23: =COUNTIFS('KEG. PENGAJIAN HARIAN'!$F$2:$F979,B23,'KEG. PENGAJIAN HARIAN'!$B$2:$B979,">="&$E$2,'KEG. PENGAJIAN HARIAN'!$B$2:$B979,"<="&$G$2,'KEG. PENGAJIAN HARIAN'!$G$2:$G979,"By VN") -> 0 | J23: =COUNTIFS('KEG. PENGAJIAN HARIAN'!$F$2:$F979,B23,'KEG. PENGAJIAN HARIAN'!$B$2:$B979,">="&$E$2,'KEG. PENGAJIAN HARIAN'!$B$2:$B979,"<="&$G$2,'KEG. PENGAJIAN HARIAN'!$G$2:$G979,"izin (murid)") -> 0 | K23: PraRMJ-RMJ | L23: =countif(D22:D42,"PraRMJ-RMJ") -> 7
A24: 3 | B24: Chester-PD | C24: New Hampshire | D24: PraCBR-CBR | E24: =sumifs('KEG. PENGAJIAN HARIAN'!$D$2:$D979,'KEG. PENGAJIAN HARIAN'!$B$2:$B979,">="&$E$2,'KEG. PENGAJIAN HARIAN'!$B$2:$B979,"<="&$G$2,'KEG. PENGAJIAN HARIAN'!$F$2:$F979,B24) -> 0.39444444 | F24: 0.5 | G24: =IFERROR(E24/F24,0) -> 0.78888889 | H24: =COUNTIFS('KEG. PENGAJIAN HARIAN'!$F$2:$F979,B24,'KEG. PENGAJIAN HARIAN'!$B$2:$B979,">="&$E$2,'KEG. PENGAJIAN HARIAN'!$B$2:$B979,"<="&$G$2,'KEG. PENGAJIAN HARIAN'!$G$2:$G979,"hadir") -> 9 | I24: =COUNTIFS('KEG. PENGAJIAN HARIAN'!$F$2:$F979,B24,'KEG. PENGAJIAN HARIAN'!$B$2:$B979,">="&$E$2,'KEG. PENGAJIAN HARIAN'!$B$2:$B979,"<="&$G$2,'KEG. PENGAJIAN HARIAN'!$G$2:$G979,"By VN") -> 0 | J24: =COUNTIFS('KEG. PENGAJIAN HARIAN'!$F$2:$F979,B24,'KEG. PENGAJIAN HARIAN'!$B$2:$B979,">="&$E$2,'KEG. PENGAJIAN HARIAN'!$B$2:$B979,"<="&$G$2,'KEG. PENGAJIAN HARIAN'!$G$2:$G979,"izin (murid)") -> 0 | K24: PraNIkah | L24: =countif(D22:D42,"PraNikah") -> 4
A25: 4 | B25: Dawud-RLG | C25: New Hampshire | D25: PraCBR-CBR | E25: =sumifs('KEG. PENGAJIAN HARIAN'!$D$2:$D979,'KEG. PENGAJIAN HARIAN'!$B$2:$B979,">="&$E$2,'KEG. PENGAJIAN HARIAN'!$B$2:$B979,"<="&$G$2,'KEG. PENGAJIAN HARIAN'!$F$2:$F979,B25) -> 0.15555556 | F25: 0.5 | G25: =IFERROR(E25/F25,0) -> 0.31111111 | H25: =COUNTIFS('KEG. PENGAJIAN HARIAN'!$F$2:$F979,B25,'KEG. PENGAJIAN HARIAN'!$B$2:$B979,">="&$E$2,'KEG. PENGAJIAN HARIAN'!$B$2:$B979,"<="&$G$2,'KEG. PENGAJIAN HARIAN'!$G$2:$G979,"hadir") -> 6 | I25: =COUNTIFS('KEG. PENGAJIAN HARIAN'!$F$2:$F979,B25,'KEG. PENGAJIAN HARIAN'!$B$2:$B979,">="&$E$2,'KEG. PENGAJIAN HARIAN'!$B$2:$B979,"<="&$G$2,'KEG. PENGAJIAN HARIAN'!$G$2:$G979,"By VN") -> 0 | J25: =COUNTIFS('KEG. PENGAJIAN HARIAN'!$F$2:$F979,B25,'KEG. PENGAJIAN HARIAN'!$B$2:$B979,">="&$E$2,'KEG. PENGAJIAN HARIAN'!$B$2:$B979,"<="&$G$2,'KEG. PENGAJIAN HARIAN'!$G$2:$G979,"izin (murid)") -> 0
A26: 5 | B26: Dehan-CND | C26: Canada | D26: PraRMJ-RMJ | E26: =sumifs('KEG. PENGAJIAN HARIAN'!$D$2:$D979,'KEG. PENGAJIAN HARIAN'!$B$2:$B979,">="&$E$2,'KEG. PENGAJIAN HARIAN'!$B$2:$B979,"<="&$G$2,'KEG. PENGAJIAN HARIAN'!$F$2:$F979,B26) -> 0.14791667 | F26: 0.5 | G26: =IFERROR(E26/F26,0) -> 0.29583333 | H26: =COUNTIFS('KEG. PENGAJIAN HARIAN'!$F$2:$F979,B26,'KEG. PENGAJIAN HARIAN'!$B$2:$B979,">="&$E$2,'KEG. PENGAJIAN HARIAN'!$B$2:$B979,"<="&$G$2,'KEG. PENGAJIAN HARIAN'!$G$2:$G979,"hadir") -> 6 | I26: =COUNTIFS('KEG. PENGAJIAN HARIAN'!$F$2:$F979,B26,'KEG. PENGAJIAN HARIAN'!$B$2:$B979,">="&$E$2,'KEG. PENGAJIAN HARIAN'!$B$2:$B979,"<="&$G$2,'KEG. PENGAJIAN HARIAN'!$G$2:$G979,"By VN") -> 0 | J26: =COUNTIFS('KEG. PENGAJIAN HARIAN'!$F$2:$F979,B26,'KEG. PENGAJIAN HARIAN'!$B$2:$B979,">="&$E$2,'KEG. PENGAJIAN HARIAN'!$B$2:$B979,"<="&$G$2,'KEG. PENGAJIAN HARIAN'!$G$2:$G979,"izin (murid)") -> 0 | K26: Chicago | L26: =countif(C22:C42,"Chicago") -> 10 | M26: =sumif(C22:C42,"Chicago",F22:F42) -> 5
A27: 6 | B27: Denissa-RLG | C27: New Hampshire | D27: PraRMJ-RMJ | E27: =sumifs('KEG. PENGAJIAN HARIAN'!$D$2:$D979,'KEG. PENGAJIAN HARIAN'!$B$2:$B979,">="&$E$2,'KEG. PENGAJIAN HARIAN'!$B$2:$B979,"<="&$G$2,'KEG. PENGAJIAN HARIAN'!$F$2:$F979,B27) -> 0.095833333 | F27: 0.5 | G27: =IFERROR(E27/F27,0) -> 0.19166667 | H27: =COUNTIFS('KEG. PENGAJIAN HARIAN'!$F$2:$F979,B27,'KEG. PENGAJIAN HARIAN'!$B$2:$B979,">="&$E$2,'KEG. PENGAJIAN HARIAN'!$B$2:$B979,"<="&$G$2,'KEG. PENGAJIAN HARIAN'!$G$2:$G979,"hadir") -> 2 | I27: =COUNTIFS('KEG. PENGAJIAN HARIAN'!$F$2:$F979,B27,'KEG. PENGAJIAN HARIAN'!$B$2:$B979,">="&$E$2,'KEG. PENGAJIAN HARIAN'!$B$2:$B979,"<="&$G$2,'KEG. PENGAJIAN HARIAN'!$G$2:$G979,"By VN") -> 1 | J27: =COUNTIFS('KEG. PENGAJIAN HARIAN'!$F$2:$F979,B27,'KEG. PENGAJIAN HARIAN'!$B$2:$B979,">="&$E$2,'KEG. PENGAJIAN HARIAN'!$B$2:$B979,"<="&$G$2,'KEG. PENGAJIAN HARIAN'!$G$2:$G979,"izin (murid)") -> 0 | K27: California | L27: =countif(C22:C42,"California") -> 4 | M27: =sumif(C22:C42,"California",F22:F42) -> 2
A28: 7 | B28: Dinda-RLG | C28: New Hampshire | D28: PraCBR-CBR | E28: =sumifs('KEG. PENGAJIAN HARIAN'!$D$2:$D979,'KEG. PENGAJIAN HARIAN'!$B$2:$B979,">="&$E$2,'KEG. PENGAJIAN HARIAN'!$B$2:$B979,"<="&$G$2,'KEG. PENGAJIAN HARIAN'!$F$2:$F979,B28) -> 0.26875 | F28: 0.5 | G28: =IFERROR(E28/F28,0) -> 0.5375 | H28: =COUNTIFS('KEG. PENGAJIAN HARIAN'!$F$2:$F979,B28,'KEG. PENGAJIAN HARIAN'!$B$2:$B979,">="&$E$2,'KEG. PENGAJIAN HARIAN'!$B$2:$B979,"<="&$G$2,'KEG. PENGAJIAN HARIAN'!$G$2:$G979,"hadir") -> 6 | I28: =COUNTIFS('KEG. PENGAJIAN HARIAN'!$F$2:$F979,B28,'KEG. PENGAJIAN HARIAN'!$B$2:$B979,">="&$E$2,'KEG. PENGAJIAN HARIAN'!$B$2:$B979,"<="&$G$2,'KEG. PENGAJIAN HARIAN'!$G$2:$G979,"By VN") -> 0 | J28: =COUNTIFS('KEG. PENGAJIAN HARIAN'!$F$2:$F979,B28,'KEG. PENGAJIAN HARIAN'!$B$2:$B979,">="&$E$2,'KEG. PENGAJIAN HARIAN'!$B$2:$B979,"<="&$G$2,'KEG. PENGAJIAN HARIAN'!$G$2:$G979,"izin (murid)") -> 1 | K28: New Hampshire | L28: =countif(C22:C42,"New Hampshire") -> 5 | M28: =sumif(C22:C42,"New Hampshire",F22:F42) -> 2.5
A29: 8 | B29: Dwiki-RLG | C29: New Hampshire | D29: PraRMJ-RMJ | E29: =sumifs('KEG. PENGAJIAN HARIAN'!$D$2:$D979,'KEG. PENGAJIAN HARIAN'!$B$2:$B979,">="&$E$2,'KEG. PENGAJIAN HARIAN'!$B$2:$B979,"<="&$G$2,'KEG. PENGAJIAN HARIAN'!$F$2:$F979,B29) -> 0.26319444 | F29: 0.5 | G29: =IFERROR(E29/F29,0) -> 0.52638889 | H29: =COUNTIFS('KEG. PENGAJIAN HARIAN'!$F$2:$F979,B29,'KEG. PENGAJIAN HARIAN'!$B$2:$B979,">="&$E$2,'KEG. PENGAJIAN HARIAN'!$B$2:$B979,"<="&$G$2,'KEG. PENGAJIAN HARIAN'!$G$2:$G979,"hadir") -> 7 | I29: =COUNTIFS('KEG. PENGAJIAN HARIAN'!$F$2:$F979,B29,'KEG. PENGAJIAN HARIAN'!$B$2:$B979,">="&$E$2,'KEG. PENGAJIAN HARIAN'!$B$2:$B979,"<="&$G$2,'KEG. PENGAJIAN HARIAN'!$G$2:$G979,"By VN") -> 0 | J29: =COUNTIFS('KEG. PENGAJIAN HARIAN'!$F$2:$F979,B29,'KEG. PENGAJIAN HARIAN'!$B$2:$B979,">="&$E$2,'KEG. PENGAJIAN HARIAN'!$B$2:$B979,"<="&$G$2,'KEG. PENGAJIAN HARIAN'!$G$2:$G979,"izin (murid)") -> 0 | K29: Canada | L29: =countif(C22:C42,"Canada") -> 2 | M29: =sumif(C22:C42,"Canada",F22:F42) -> 1
A30: 9 | B30: Dylan-CA | C30: California | D30: PraRMJ-RMJ | E30: =sumifs('KEG. PENGAJIAN HARIAN'!$D$2:$D979,'KEG. PENGAJIAN HARIAN'!$B$2:$B979,">="&$E$2,'KEG. PENGAJIAN HARIAN'!$B$2:$B979,"<="&$G$2,'KEG. PENGAJIAN HARIAN'!$F$2:$F979,B30) -> 0.20069444 | F30: 0.5 | G30: =IFERROR(E30/F30,0) -> 0.40138889 | H30: =COUNTIFS('KEG. PENGAJIAN HARIAN'!$F$2:$F979,B30,'KEG. PENGAJIAN HARIAN'!$B$2:$B979,">="&$E$2,'KEG. PENGAJIAN HARIAN'!$B$2:$B979,"<="&$G$2,'KEG. PENGAJIAN HARIAN'!$G$2:$G979,"hadir") -> 9 | I30: =COUNTIFS('KEG. PENGAJIAN HARIAN'!$F$2:$F979,B30,'KEG. PENGAJIAN HARIAN'!$B$2:$B979,">="&$E$2,'KEG. PENGAJIAN HARIAN'!$B$2:$B979,"<="&$G$2,'KEG. PENGAJIAN HARIAN'!$G$2:$G979,"By VN") -> 0 | J30: =COUNTIFS('KEG. PENGAJIAN HARIAN'!$F$2:$F979,B30,'KEG. PENGAJIAN HARIAN'!$B$2:$B979,">="&$E$2,'KEG. PENGAJIAN HARIAN'!$B$2:$B979,"<="&$G$2,'KEG. PENGAJIAN HARIAN'!$G$2:$G979,"izin (murid)") -> 0
A31: 10 | B31: Fitri-CND | C31: Canada | D31: PraRMJ-RMJ | E31: =sumifs('KEG. PENGAJIAN HARIAN'!$D$2:$D979,'KEG. PENGAJIAN HARIAN'!$B$2:$B979,">="&$E$2,'KEG. PENGAJIAN HARIAN'!$B$2:$B979,"<="&$G$2,'KEG. PENGAJIAN HARIAN'!$F$2:$F979,B31) -> 0.23819444 | F31: 0.5 | G31: =IFERROR(E31/F31,0) -> 0.47638889 | H31: =COUNTIFS('KEG. PENGAJIAN HARIAN'!$F$2:$F979,B31,'KEG. PENGAJIAN HARIAN'!$B$2:$B979,">="&$E$2,'KEG. PENGAJIAN HARIAN'!$B$2:$B979,"<="&$G$2,'KEG. PENGAJIAN HARIAN'!$G$2:$G979,"hadir") -> 4 | I31: =COUNTIFS('KEG. PENGAJIAN HARIAN'!$F$2:$F979,B31,'KEG. PENGAJIAN HARIAN'!$B$2:$B979,">="&$E$2,'KEG. PENGAJIAN HARIAN'!$B$2:$B979,"<="&$G$2,'KEG. PENGAJIAN HARIAN'!$G$2:$G979,"By VN") -> 0 | J31: =COUNTIFS('KEG. PENGAJIAN HARIAN'!$F$2:$F979,B31,'KEG. PENGAJIAN HARIAN'!$B$2:$B979,">="&$E$2,'KEG. PENGAJIAN HARIAN'!$B$2:$B979,"<="&$G$2,'KEG. PENGAJIAN HARIAN'!$G$2:$G979,"izin (murid)") -> 0
